Workbook

Sheet Billing Dimensions
A1: MANUAL ENTRIES HERE | C1: Box 1 Dimension Details | G1: Box 2 Dimension Details | K1: Box 3 Dimension Details | P1: Vol.Wht | Q1: Total Weight | S1: Chg.Wht | T1: Theoretical Weight
C2: Long | D2: Med | E2: Smal | F2: Actual.Wht | G2: Long | H2: Med | I2: Smal | J2: Actual.Wht | K2: Long | L2: Med | M2: Smal | N2: Actual.Wht | O2: CBF | P2: 6 | Q2: Phys.Wht | R2: Wht(Kgs) | U2: Difference | V2: Diff % | W2: KG/CBF | Y2: Remark
A3: MTP SKU Code | B3: SB/MB | C3: Lcm | D3: Bcm | E3: Hcm | F3: PW(gm) | G3: Lcm2 | H3: Bcm3 | I3: Hcm4 | J3: PW(gm)5 | K3: Lcm6 | L3: Bcm7 | M3: Hcm8 | N3: PW(gm)9 | O3: Column15 | P3: Kgs | Q3: Gms | R3: Kgs10 | S3: Column11 | T3: Column12 | U3: Column13 | V3: Column14 | W3: Column16 | X3: x | Y3: Remark
A4: B-MLT-KT | B4: MB | C4: 204 | D4: 39 | E4: 6 | F4: 26800 | G4: 190 | H4: 80 | I4: 6 | J4: 32100 | K4: 107 | L4: 96 | M4: 7 | N4: 40400 | O4: =((IFERROR((C4*D4*E4),0)+IFERROR((G4*H4*I4),0)+IFERROR((K4*L4*M4),0))/1000000)*35.32 -> 7.4468688 | P4: =F4+J4+N4 -> 99300 | Q4: =F4+J4+N4 -> 99300 | R4: =MAX(Q4,O4) -> 99300 | S4: =MAX(R4,P4) -> 99300 | T4: =MAX(S4,Q4) -> 99300 | U4: =T4-Q4 -> 0 | V4: =U4/T4 -> 0 | W4: =R4/O4 -> 13334.463 | Y4: phy. not avilable
A5: B-MLT-QT | B5: MB | C5: 204 | D5: 39 | E5: 7 | F5: 25770 | G5: 162 | H5: 81 | I5: 5 | J5: 28000 | K5: 104 | L5: 80 | M5: 7 | N5: 35000 | O5: =((IFERROR((C5*D5*E5),0)+IFERROR((G5*H5*I5),0)+IFERROR((K5*L5*M5),0))/1000000)*35.32 -> 6.3414234 | P5: =F5+J5+N5 -> 88770 | Q5: =F5+J5+N5 -> 88770 | R5: =MAX(Q5,O5) -> 88770 | S5: =MAX(R5,P5) -> 88770 | T5: =MAX(S5,Q5) -> 88770 | U5: =T5-Q5 -> 0 | V5: =U5/T5 -> 0 | W5: =R5/O5 -> 13998.434 | Y5: ok
A6: B-POL-KN | B6: MB | C6: 205 | D6: 54 | E6: 10 | F6: 35000 | G6: 105 | H6: 94 | I6: 5 | J6: 35000 | O6: =((IFERROR((C6*D6*E6),0)+IFERROR((G6*H6*I6),0)+IFERROR((K6*L6*M6),0))/1000000)*35.32 -> 5.652966 | P6: =F6+J6+N6 -> 70000 | Q6: =F6+J6+N6 -> 70000 | R6: =MAX(Q6,O6) -> 70000 | S6: =MAX(R6,P6) -> 70000 | T6: =MAX(S6,Q6) -> 70000 | U6: =T6-Q6 -> 0 | V6: =U6/T6 -> 0 | W6: =R6/O6 -> 12382.88 | Y6: phy. not avilable
A7: B-POL-KT | B7: MB | C7: 207 | D7: 38 | E7: 8 | F7: 34800 | G7: 192 | H7: 40 | I7: 6 | J7: 22700 | K7: 105 | L7: 96 | M7: 7 | N7: 38800 | O7: =((IFERROR((C7*D7*E7),0)+IFERROR((G7*H7*I7),0)+IFERROR((K7*L7*M7),0))/1000000)*35.32 -> 6.3423418 | P7: =F7+J7+N7 -> 96300 | Q7: =F7+J7+N7 -> 96300 | R7: =MAX(Q7,O7) -> 96300 | S7: =MAX(R7,P7) -> 96300 | T7: =MAX(S7,Q7) -> 96300 | U7: =T7-Q7 -> 0 | V7: =U7/T7 -> 0 | W7: =R7/O7 -> 15183.666 | Y7: ok
A8: B-POL-QN | B8: MB | C8: 206 | D8: 50 | E8: 10 | F8: 46000 | G8: 102 | H8: 79 | I8: 5 | J8: 24000 | O8: =((IFERROR((C8*D8*E8),0)+IFERROR((G8*H8*I8),0)+IFERROR((K8*L8*M8),0))/1000000)*35.32 -> 5.0610028 | P8: =F8+J8+N8 -> 70000 | Q8: =F8+J8+N8 -> 70000 | R8: =MAX(Q8,O8) -> 70000 | S8: =MAX(R8,P8) -> 70000 | T8: =MAX(S8,Q8) -> 70000 | U8: =T8-Q8 -> 0 | V8: =U8/T8 -> 0 | W8: =R8/O8 -> 13831.251 | Y8: phy. not avilable
A9: B-POL-QT | B9: MB | C9: 202 | D9: 40 | E9: 9 | F9: 34290 | G9: 162 | H9: 40 | I9: 6 | J9: 18850 | K9: 104 | L9: 82 | M9: 7 | N9: 37400 | O9: =((IFERROR((C9*D9*E9),0)+IFERROR((G9*H9*I9),0)+IFERROR((K9*L9*M9),0))/1000000)*35.32 -> 6.0501747 | P9: =F9+J9+N9 -> 90540 | Q9: =F9+J9+N9 -> 90540 | R9: =MAX(Q9,O9) -> 90540 | S9: =MAX(R9,P9) -> 90540 | T9: =MAX(S9,Q9) -> 90540 | U9: =T9-Q9 -> 0 | V9: =U9/T9 -> 0 | W9: =R9/O9 -> 14964.857 | Y9: ok
A10: B-POL-SN | B10: MB | C10: 204 | D10: 48 | E10: 6 | F10: 31000 | G10: 106 | H10: 96 | I10: 3 | J10: 15100 | O10: =((IFERROR((C10*D10*E10),0)+IFERROR((G10*H10*I10),0)+IFERROR((K10*L10*M10),0))/1000000)*35.32 -> 3.1533696 | P10: =F10+J10+N10 -> 46100 | Q10: =F10+J10+N10 -> 46100 | R10: =MAX(Q10,O10) -> 46100 | S10: =MAX(R10,P10) -> 46100 | T10: =MAX(S10,Q10) -> 46100 | U10: =T10-Q10 -> 0 | V10: =U10/T10 -> 0 | W10: =R10/O10 -> 14619.282 | Y10: ok
A11: B-RVB-D30N | O11: =((IFERROR((C11*D11*E11),0)+IFERROR((G11*H11*I11),0)+IFERROR((K11*L11*M11),0))/1000000)*35.32 -> 0 | P11: =F11+J11+N11 -> 0 | Q11: =F11+J11+N11 -> 0 | R11: =MAX(Q11,O11) -> 0 | S11: =MAX(R11,P11) -> 0 | T11: =MAX(S11,Q11) -> 0 | U11: =T11-Q11 -> 0 | V11: =U11/T11 -> #DIV/0! | W11: =R11/O11 -> #DIV/0! | Y11: phy. not avilable
A12: B-RVB-D36N | B12: SB | C12: 188 | D12: 44 | E12: 9 | F12: 33270 | O12: =((IFERROR((C12*D12*E12),0)+IFERROR((G12*H12*I12),0)+IFERROR((K12*L12*M12),0))/1000000)*35.32 -> 2.6295034 | P12: =F12+J12+N12 -> 33270 | Q12: =F12+J12+N12 -> 33270 | R12: =MAX(Q12,O12) -> 33270 | S12: =MAX(R12,P12) -> 33270 | T12: =MAX(S12,Q12) -> 33270 | U12: =T12-Q12 -> 0 | V12: =U12/T12 -> 0 | W12: =R12/O12 -> 12652.579 | Y12: ok
A13: B-RVB-KN | B13: MB | C13: 206 | D13: 50 | E13: 8 | F13: 45600 | G13: 105 | H13: 96 | I13: 5 | J13: 27600 | O13: =((IFERROR((C13*D13*E13),0)+IFERROR((G13*H13*I13),0)+IFERROR((K13*L13*M13),0))/1000000)*35.32 -> 4.690496 | P13: =F13+J13+N13 -> 73200 | Q13: =IFERROR(F13,0)+IFERROR(J13,0)+IFERROR(N13,0) -> 73200 | R13: =MAX(Q13,O13) -> 73200 | S13: =MAX(R13,P13) -> 73200 | T13: =MAX(S13,Q13) -> 73200 | U13: =T13-Q13 -> 0 | V13: =U13/T13 -> 0 | W13: =R13/O13 -> 15606.025 | Y13: ok
A14: B-RVB-QN | B14: MB | C14: 205 | D14: 50 | E14: 8 | F14: 41950 | G14: 104 | H14: 84 | I14: 5 | J14: 23100 | O14: =((IFERROR((C14*D14*E14),0)+IFERROR((G14*H14*I14),0)+IFERROR((K14*L14*M14),0))/1000000)*35.32 -> 4.4390176 | P14: =F14+J14+N14 -> 65050 | Q14: =F14+J14+N14 -> 65050 | R14: =MAX(Q14,O14) -> 65050 | S14: =MAX(R14,P14) -> 65050 | T14: =MAX(S14,Q14) -> 65050 | U14: =T14-Q14 -> 0 | V14: =U14/T14 -> 0 | W14: =R14/O14 -> 14654.143 | Y14: ok
A15: B-RVB-SN | B15: MB | C15: 199 | D15: 38 | E15: 9 | F15: 30460 | G15: 99 | H15: 54 | I15: 5 | J15: 16000 | O15: =((IFERROR((C15*D15*E15),0)+IFERROR((G15*H15*I15),0)+IFERROR((K15*L15*M15),0))/1000000)*35.32 -> 3.3479122 | P15: =F15+J15+N15 -> 46460 | Q15: =F15+J15+N15 -> 46460 | R15: =MAX(Q15,O15) -> 46460 | S15: =MAX(R15,P15) -> 46460 | T15: =MAX(S15,Q15) -> 46460 | U15: =T15-Q15 -> 0 | V15: =U15/T15 -> 0 | W15: =R15/O15 -> 13877.306 | Y15: ok
A16: BT-CO | B16: SB | C16: 72 | D16: 39 | E16: 5 | F16: 6470 | O16: =((IFERROR((C16*D16*E16),0)+IFERROR((G16*H16*I16),0)+IFERROR((K16*L16*M16),0))/1000000)*35.32 -> 0.4958928 | P16: =F16+J16+N16 -> 6470 | Q16: =F16+J16+N16 -> 6470 | R16: =MAX(Q16,O16) -> 6470 | S16: =MAX(R16,P16) -> 6470 | T16: =MAX(S16,Q16) -> 6470 | U16: =T16-Q16 -> 0 | V16: =U16/T16 -> 0 | W16: =R16/O16 -> 13047.175 | Y16: ok
A17: BT-HE | B17: SB | C17: 42 | D17: 41 | E17: 6 | F17: 4300 | O17: =((IFERROR((C17*D17*E17),0)+IFERROR((G17*H17*I17),0)+IFERROR((K17*L17*M17),0))/1000000)*35.32 -> 0.36492624 | P17: =F17+J17+N17 -> 4300 | Q17: =F17+J17+N17 -> 4300 | R17: =MAX(Q17,O17) -> 4300 | S17: =MAX(R17,P17) -> 4300 | T17: =MAX(S17,Q17) -> 4300 | U17: =T17-Q17 -> 0 | V17: =U17/T17 -> 0 | W17: =R17/O17 -> 11783.203 | Y17: ok
A18: BT-LE-B | B18: ` | C18: 64 | D18: 58 | E18: 12 | F18: 15000 | O18: =((IFERROR((C18*D18*E18),0)+IFERROR((G18*H18*I18),0)+IFERROR((K18*L18*M18),0))/1000000)*35.32 -> 1.5732941 | P18: =F18+J18+N18 -> 15000 | Q18: =F18+J18+N18 -> 15000 | R18: =MAX(Q18,O18) -> 15000 | S18: =MAX(R18,P18) -> 15000 | T18: =MAX(S18,Q18) -> 15000 | U18: =T18-Q18 -> 0 | V18: =U18/T18 -> 0 | W18: =R18/O18 -> 9534.1362 | Y18: phy. not avilable
A19: BT-LE-S | O19: =((IFERROR((C19*D19*E19),0)+IFERROR((G19*H19*I19),0)+IFERROR((K19*L19*M19),0))/1000000)*35.32 -> 0 | P19: =F19+J19+N19 -> 0 | Q19: =F19+J19+N19 -> 0 | R19: =MAX(Q19,O19) -> 0 | S19: =MAX(R19,P19) -> 0 | T19: =MAX(S19,Q19) -> 0 | U19: =T19-Q19 -> 0 | V19: =U19/T19 -> #DIV/0! | W19: =R19/O19 -> #DIV/0! | Y19: phy. not avilable
A20: BT-OL | B20: SB | C20: 48 | D20: 45 | E20: 5 | F20: 7700 | O20: =((IFERROR((C20*D20*E20),0)+IFERROR((G20*H20*I20),0)+IFERROR((K20*L20*M20),0))/1000000)*35.32 -> 0.381456 | P20: =F20+J20+N20 -> 7700 | Q20: =F20+J20+N20 -> 7700 | R20: =MAX(Q20,O20) -> 7700 | S20: =MAX(R20,P20) -> 7700 | T20: =MAX(S20,Q20) -> 7700 | U20: =T20-Q20 -> 0 | V20: =U20/T20 -> 0 | W20: =R20/O20 -> 20185.814 | Y20: ok
A21: BT-OL-D | B21: SB | C21: 60 | D21: 44 | E21: 7 | F21: 10490 | O21: =((IFERROR((C21*D21*E21),0)+IFERROR((G21*H21*I21),0)+IFERROR((K21*L21*M21),0))/1000000)*35.32 -> 0.6527136 | P21: =F21+J21+N21 -> 10490 | Q21: =F21+J21+N21 -> 10490 | R21: =MAX(Q21,O21) -> 10490 | S21: =MAX(R21,P21) -> 10490 | T21: =MAX(S21,Q21) -> 10490 | U21: =T21-Q21 -> 0 | V21: =U21/T21 -> 0 | W21: =R21/O21 -> 16071.367 | Y21: ok
A22: CMB-RELO | O22: =((IFERROR((C22*D22*E22),0)+IFERROR((G22*H22*I22),0)+IFERROR((K22*L22*M22),0))/1000000)*35.32 -> 0 | P22: =F22+J22+N22 -> 0 | Q22: =F22+J22+N22 -> 0 | R22: =MAX(Q22,O22) -> 0 | S22: =MAX(R22,P22) -> 0 | T22: =MAX(S22,Q22) -> 0 | U22: =T22-Q22 -> 0 | V22: =U22/T22 -> #DIV/0! | W22: =R22/O22 -> #DIV/0! | Y22: phy. not avilable
A23: CT-ATD-LA | B23: SB | C23: 123 | D23: 56 | E23: 5 | F23: 24490 | O23: =((IFERROR((C23*D23*E23),0)+IFERROR((G23*H23*I23),0)+IFERROR((K23*L23*M23),0))/1000000)*35.32 -> 1.2164208 | P23: =F23+J23+N23 -> 24490 | Q23: =F23+J23+N23 -> 24490 | R23: =MAX(Q23,O23) -> 24490 | S23: =MAX(R23,P23) -> 24490 | T23: =MAX(S23,Q23) -> 24490 | U23: =T23-Q23 -> 0 | V23: =U23/T23 -> 0 | W23: =R23/O23 -> 20132.836 | Y23: phy. not avilable
A24: CT-ATD | B24: SB | F24: 15800 | O24: =((IFERROR((C24*D24*E24),0)+IFERROR((G24*H24*I24),0)+IFERROR((K24*L24*M24),0))/1000000)*35.32 -> 0 | P24: =F24+J24+N24 -> 15800 | Q24: =F24+J24+N24 -> 15800 | R24: =MAX(Q24,O24) -> 15800 | S24: =MAX(R24,P24) -> 15800 | T24: =MAX(S24,Q24) -> 15800 | U24: =T24-Q24 -> 0 | V24: =U24/T24 -> 0 | W24: =R24/O24 -> #DIV/0! | Y24: phy. not avilable
A25: CT-ATD-ST | B25: SB | C25: 112 | D25: 51 | E25: 5 | F25: 14800 | O25: =((IFERROR((C25*D25*E25),0)+IFERROR((G25*H25*I25),0)+IFERROR((K25*L25*M25),0))/1000000)*35.32 -> 1.0087392 | P25: =F25+J25+N25 -> 14800 | Q25: =F25+J25+N25 -> 14800 | R25: =MAX(Q25,O25) -> 14800 | S25: =MAX(R25,P25) -> 14800 | T25: =MAX(S25,Q25) -> 14800 | U25: =T25-Q25 -> 0 | V25: =U25/T25 -> 0 | W25: =R25/O25 -> 14671.78 | Y25: ok
A26: CT-DOV | B26: SB | C26: 111 | D26: 50 | E26: 8 | F26: 21750 | O26: =((IFERROR((C26*D26*E26),0)+IFERROR((G26*H26*I26),0)+IFERROR((K26*L26*M26),0))/1000000)*35.32 -> 1.568208 | P26: =F26+J26+N26 -> 21750 | Q26: =F26+J26+N26 -> 21750 | R26: =MAX(Q26,O26) -> 21750 | S26: =MAX(R26,P26) -> 21750 | T26: =MAX(S26,Q26) -> 21750 | U26: =T26-Q26 -> 0 | V26: =U26/T26 -> 0 | W26: =R26/O26 -> 13869.334 | Y26: ok
A27: CT-ETE | B27: SB | C27: 106 | D27: 50 | E27: 7 | F27: 12400 | O27: =((IFERROR((C27*D27*E27),0)+IFERROR((G27*H27*I27),0)+IFERROR((K27*L27*M27),0))/1000000)*35.32 -> 1.310372 | P27: =F27+J27+N27 -> 12400 | Q27: =F27+J27+N27 -> 12400 | R27: =MAX(Q27,O27) -> 12400 | S27: =MAX(R27,P27) -> 12400 | T27: =MAX(S27,Q27) -> 12400 | U27: =T27-Q27 -> 0 | V27: =U27/T27 -> 0 | W27: =R27/O27 -> 9462.9617 | Y27: ok
A28: CT-GSE-RT | B28: SB | C28: 99 | D28: 50 | E28: 4 | F28: 6120 | O28: =((IFERROR((C28*D28*E28),0)+IFERROR((G28*H28*I28),0)+IFERROR((K28*L28*M28),0))/1000000)*35.32 -> 0.699336 | P28: =F28+J28+N28 -> 6120 | Q28: =F28+J28+N28 -> 6120 | R28: =MAX(Q28,O28) -> 6120 | S28: =MAX(R28,P28) -> 6120 | T28: =MAX(S28,Q28) -> 6120 | U28: =T28-Q28 -> 0 | V28: =U28/T28 -> 0 | W28: =R28/O28 -> 8751.1582 | Y28: ok
A29: CT-GSE-RT2 | B29: SB | C29: 98 | D29: 51 | E29: 4 | F29: 11390 | O29: =((IFERROR((C29*D29*E29),0)+IFERROR((G29*H29*I29),0)+IFERROR((K29*L29*M29),0))/1000000)*35.32 -> 0.70611744 | P29: =F29+J29+N29 -> 11390 | Q29: =F29+J29+N29 -> 11390 | R29: =MAX(Q29,O29) -> 11390 | S29: =MAX(R29,P29) -> 11390 | T29: =MAX(S29,Q29) -> 11390 | U29: =T29-Q29 -> 0 | V29: =U29/T29 -> 0 | W29: =R29/O29 -> 16130.461 | Y29: ok
A30: CT-GSE-SQ | B30: SB | C30: 75 | D30: 75 | E30: 4 | F30: 8200 | O30: =((IFERROR((C30*D30*E30),0)+IFERROR((G30*H30*I30),0)+IFERROR((K30*L30*M30),0))/1000000)*35.32 -> 0.7947 | P30: =F30+J30+N30 -> 8200 | Q30: =F30+J30+N30 -> 8200 | R30: =MAX(Q30,O30) -> 8200 | S30: =MAX(R30,P30) -> 8200 | T30: =MAX(S30,Q30) -> 8200 | U30: =T30-Q30 -> 0 | V30: =U30/T30 -> 0 | W30: =R30/O30 -> 10318.359 | Y30: ok
A31: CT-GSE-SQ2 | B31: SB | C31: 76 | D31: 76 | E31: 4 | F31: 12200 | O31: =((IFERROR((C31*D31*E31),0)+IFERROR((G31*H31*I31),0)+IFERROR((K31*L31*M31),0))/1000000)*35.32 -> 0.81603328 | P31: =F31+J31+N31 -> 12200 | Q31: =F31+J31+N31 -> 12200 | R31: =MAX(Q31,O31) -> 12200 | S31: =MAX(R31,P31) -> 12200 | T31: =MAX(S31,Q31) -> 12200 | U31: =T31-Q31 -> 0 | V31: =U31/T31 -> 0 | W31: =R31/O31 -> 14950.371 | Y31: ok
A32: CT-KV-RT | B32: SB | C32: 105 | D32: 51 | E32: 7 | F32: 11800 | O32: =((IFERROR((C32*D32*E32),0)+IFERROR((G32*H32*I32),0)+IFERROR((K32*L32*M32),0))/1000000)*35.32 -> 1.3239702 | P32: =F32+J32+N32 -> 11800 | Q32: =F32+J32+N32 -> 11800 | R32: =MAX(Q32,O32) -> 11800 | S32: =MAX(R32,P32) -> 11800 | T32: =MAX(S32,Q32) -> 11800 | U32: =T32-Q32 -> 0 | V32: =U32/T32 -> 0 | W32: =R32/O32 -> 8912.5873 | Y32: phy. not avilable
A33: CT-KV-SQ | B33: SB | C33: 81 | D33: 80 | E33: 7 | F33: 16900 | O33: =((IFERROR((C33*D33*E33),0)+IFERROR((G33*H33*I33),0)+IFERROR((K33*L33*M33),0))/1000000)*35.32 -> 1.6021152 | P33: =F33+J33+N33 -> 16900 | Q33: =F33+J33+N33 -> 16900 | R33: =MAX(Q33,O33) -> 16900 | S33: =MAX(R33,P33) -> 16900 | T33: =MAX(S33,Q33) -> 16900 | U33: =T33-Q33 -> 0 | V33: =U33/T33 -> 0 | W33: =R33/O33 -> 10548.555 | Y33: ok
A34: CT-LE | B34: SB | C34: 114 | D34: 56 | E34: 7 | F34: 10850 | O34: =((IFERROR((C34*D34*E34),0)+IFERROR((G34*H34*I34),0)+IFERROR((K34*L34*M34),0))/1000000)*35.32 -> 1.5783802 | P34: =F34+J34+N34 -> 10850 | Q34: =F34+J34+N34 -> 10850 | R34: =MAX(Q34,O34) -> 10850 | S34: =MAX(R34,P34) -> 10850 | T34: =MAX(S34,Q34) -> 10850 | U34: =T34-Q34 -> 0 | V34: =U34/T34 -> 0 | W34: =R34/O34 -> 6874.1361 | Y34: phy. not avilable
A35: CT-MD-RT | B35: SB | C35: 104 | D35: 60 | E35: 7 | F35: 17700 | O35: =((IFERROR((C35*D35*E35),0)+IFERROR((G35*H35*I35),0)+IFERROR((K35*L35*M35),0))/1000000)*35.32 -> 1.5427776 | P35: =F35+J35+N35 -> 17700 | Q35: =F35+J35+N35 -> 17700 | R35: =MAX(Q35,O35) -> 17700 | S35: =MAX(R35,P35) -> 17700 | T35: =MAX(S35,Q35) -> 17700 | U35: =T35-Q35 -> 0 | V35: =U35/T35 -> 0 | W35: =R35/O35 -> 11472.814 | Y35: phy. not avilable
A36: CT-MD-SQ | B36: SB | C36: 85 | D36: 84 | E36: 6 | F36: 17400 | O36: =((IFERROR((C36*D36*E36),0)+IFERROR((G36*H36*I36),0)+IFERROR((K36*L36*M36),0))/1000000)*35.32 -> 1.5131088 | P36: =F36+J36+N36 -> 17400 | Q36: =F36+J36+N36 -> 17400 | R36: =MAX(Q36,O36) -> 17400 | S36: =MAX(R36,P36) -> 17400 | T36: =MAX(S36,Q36) -> 17400 | U36: =T36-Q36 -> 0 | V36: =U36/T36 -> 0 | W36: =R36/O36 -> 11499.504 | Y36: phy. not avilable
A37: CT-MT-RO | B37: MB | C37: 70 | D37: 68 | E37: 8 | F37: 6920 | G37: 52 | H37: 12 | I37: 12 | J37: 1200 | O37: =((IFERROR((C37*D37*E37),0)+IFERROR((G37*H37*I37),0)+IFERROR((K37*L37*M37),0))/1000000)*35.32 -> 1.6094618 | P37: =F37+J37+N37 -> 8120 | Q37: =F37+J37+N37 -> 8120 | R37: =MAX(Q37,O37) -> 8120 | S37: =MAX(R37,P37) -> 8120 | T37: =MAX(S37,Q37) -> 8120 | U37: =T37-Q37 -> 0 | V37: =U37/T37 -> 0 | W37: =R37/O37 -> 5045.1649 | Y37: ok
A38: CT-MT-RT | B38: MB | C38: 100 | D38: 54 | E38: 4 | F38: 5400 | G38: 52 | H38: 12 | I38: 12 | J38: 1200 | O38: =((IFERROR((C38*D38*E38),0)+IFERROR((G38*H38*I38),0)+IFERROR((K38*L38*M38),0))/1000000)*35.32 -> 1.0273882 | P38: =F38+J38+N38 -> 6600 | Q38: =F38+J38+N38 -> 6600 | R38: =MAX(Q38,O38) -> 6600 | S38: =MAX(R38,P38) -> 6600 | T38: =MAX(S38,Q38) -> 6600 | U38: =T38-Q38 -> 0 | V38: =U38/T38 -> 0 | W38: =R38/O38 -> 6424.0569 | Y38: ok
A39: CT-MT-SQ | B39: MB | C39: 80 | D39: 80 | E39: 5 | F39: 6195 | G39: 52 | H39: 12 | I39: 12 | J39: 1200 | O39: =((IFERROR((C39*D39*E39),0)+IFERROR((G39*H39*I39),0)+IFERROR((K39*L39*M39),0))/1000000)*35.32 -> 1.3947162 | P39: =F39+J39+N39 -> 7395 | Q39: =F39+J39+N39 -> 7395 | R39: =MAX(Q39,O39) -> 7395 | S39: =MAX(R39,P39) -> 7395 | T39: =MAX(S39,Q39) -> 7395 | U39: =T39-Q39 -> 0 | V39: =U39/T39 -> 0 | W39: =R39/O39 -> 5302.1541 | Y39: ok
A40: CT-NO-RT | B40: SB | C40: 85 | D40: 45 | E40: 6 | F40: 10800 | O40: =((IFERROR((C40*D40*E40),0)+IFERROR((G40*H40*I40),0)+IFERROR((K40*L40*M40),0))/1000000)*35.32 -> 0.810594 | P40: =F40+J40+N40 -> 10800 | Q40: =F40+J40+N40 -> 10800 | R40: =MAX(Q40,O40) -> 10800 | S40: =MAX(R40,P40) -> 10800 | T40: =MAX(S40,Q40) -> 10800 | U40: =T40-Q40 -> 0 | V40: =U40/T40 -> 0 | W40: =R40/O40 -> 13323.563 | Y40: ok
...

Sheet Audit Dimensions
C1: Box 1 Dimension Details | G1: Box 2 Dimension Details | K1: Box 3 Dimension Details | O1: Vol.Wht | P1: Total Weight | R1: Chg.Wht | S1: Theoretical Weight
C2: Long | D2: Med | E2: Smal | F2: Sys.Wht | G2: Long | H2: Med | I2: Smal | J2: Sys.Wht | K2: Long | L2: Med | M2: Smal | N2: Actual.Wht | O2: 6 | P2: Actual.Wht | Q2: Wht (Kgs) | T2: Difference | U2: Diff % | V2: CBF | W2: KG/CBF | X2: Remark
A3: MTP SKU Code | B3: SB/MB | C3: Lcm | D3: Bcm | E3: Hcm | F3: PW(gm) | G3: Lcm | H3: Bcm | I3: Hcm | J3: PW(gm) | K3: Lcm | L3: Bcm | M3: Hcm | N3: PW(gm) | O3: Kgs | P3: Gms | Q3: Kgs
A4: B-MLT-KT | B4: MB | C4: 203 | D4: 39 | E4: 7 | F4: 26950 | G4: 194 | H4: 80 | I4: 5 | J4: 33000 | K4: 102 | L4: 93 | M4: 6 | N4: 38750 | O4: =V4*$O$2 -> 2270.3553 | P4: =F4+J4+N4 -> 98700 | Q4: =P4/1000 -> 98.7 | R4: =MAX(Q4,O4) -> 2270.3553 | S4: =VLOOKUP(A4,[1]Index!$E:$M,8,) -> 88614.98 | T4: =S4-P4 -> -10085.02 | U4: =T4/S4 -> -0.11380717 | V4: =(((N4*D4*E4)+(G4*H4*I4)+(K4*L4*M4))/1000000)*35.32 -> 378.39256 | W4: =Q4/V4 -> 0.26084023 | X4: phy. not avilable
A5: B-MLT-QT | B5: MB | C5: 205 | D5: 40 | E5: 7 | F5: 27250 | G5: 164 | H5: 63 | I5: 4 | J5: 23300 | K5: 102 | L5: 79 | M5: 6 | N5: 37750 | O5: =V5*$O$2 -> 31.168346 | P5: =F5+J5+N5 -> 88300 | Q5: =P5/1000 -> 88.3 | R5: =MAX(Q5,O5) -> 88.3 | S5: =VLOOKUP(A5,[1]Index!$E:$M,8,) -> 83135.099 | T5: =S5-P5 -> -5164.9015 | U5: =T5/S5 -> -0.062126605 | V5: =(((C5*D5*E5)+(G5*H5*I5)+(K5*L5*M5))/1000000)*35.32 -> 5.1947243 | W5: =Q5/V5 -> 16.998015 | X5: Ok
A6: B-POL-KN | B6: MB | O6: =V6*$O$2 -> 0 | P6: =F6+J6+N6 -> 0 | Q6: =P6/1000 -> 0 | R6: =MAX(Q6,O6) -> 0 | S6: =VLOOKUP(A6,[1]Index!$E:$M,8,) -> 70721.918 | T6: =S6-P6 -> 70721.918 | U6: =T6/S6 -> 1 | V6: =(((C6*D6*E6)+(G6*H6*I6)+(K6*L6*M6))/1000000)*35.32 -> 0 | W6: =Q6/V6 -> #DIV/0! | X6: phy. not avilable
A7: B-POL-KT | B7: MB | C7: 206 | D7: 40 | E7: 7 | F7: 36100 | G7: 149 | H7: 40 | I7: 6 | J7: 23600 | K7: 104 | L7: 79 | M7: 7 | N7: 37460 | O7: =V7*$O$2 -> 31.989748 | P7: =F7+J7+N7 -> 97160 | Q7: =P7/1000 -> 97.16 | R7: =MAX(Q7,O7) -> 97.16 | S7: =VLOOKUP(A7,[1]Index!$E:$M,8,) -> 94601.158 | T7: =S7-P7 -> -2558.842 | U7: =T7/S7 -> -0.027048739 | V7: =(((C7*D7*E7)+(G7*H7*I7)+(K7*L7*M7))/1000000)*35.32 -> 5.3316246 | W7: =Q7/V7 -> 18.223338 | X7: ok
A8: B-POL-QN | B8: MB | O8: =V8*$O$2 -> 0 | P8: =F8+J8+N8 -> 0 | Q8: =P8/1000 -> 0 | R8: =MAX(Q8,O8) -> 0 | S8: =VLOOKUP(A8,[1]Index!$E:$M,8,) -> 60043.684 | T8: =S8-P8 -> 60043.684 | U8: =T8/S8 -> 1 | V8: =(((C8*D8*E8)+(G8*H8*I8)+(K8*L8*M8))/1000000)*35.32 -> 0 | W8: =Q8/V8 -> #DIV/0! | X8: phy. not avilable
A9: B-POL-QT | B9: MB | C9: 208 | D9: 49 | E9: 7 | F9: 33800 | G9: 163 | H9: 40 | I9: 6 | J9: 20600 | K9: 101 | L9: 80 | M9: 6 | N9: 37000 | O9: =V9*$O$2 -> 33.683412 | P9: =F9+J9+N9 -> 91400 | Q9: =P9/1000 -> 91.4 | R9: =MAX(Q9,O9) -> 91.4 | S9: =VLOOKUP(A9,[1]Index!$E:$M,8,) -> 75619.774 | T9: =S9-P9 -> -15780.226 | U9: =T9/S9 -> -0.20867857 | V9: =(((C9*D9*E9)+(G9*H9*I9)+(K9*L9*M9))/1000000)*35.32 -> 5.6139021 | W9: =Q9/V9 -> 16.281011 | X9: ok
A10: B-POL-SN | B10: MB | C10: 206 | D10: 48 | E10: 6 | F10: 33550 | G10: 105 | H10: 97 | I10: 3 | J10: 14800 | O10: =V10*$O$2 -> 19.048005 | P10: =F10+J10+N10 -> 48350 | Q10: =P10/1000 -> 48.35 | R10: =MAX(Q10,O10) -> 48.35 | S10: =VLOOKUP(A10,[1]Index!$E:$M,8,) -> 40998.312 | T10: =S10-P10 -> -7351.6882 | U10: =T10/S10 -> -0.17931685 | V10: =(((C10*D10*E10)+(G10*H10*I10)+(K10*L10*M10))/1000000)*35.32 -> 3.1746676 | W10: =Q10/V10 -> 15.229941 | X10: ok.
A11: B-RVB-KN | B11: MB | C11: 207 | D11: 50 | E11: 8 | F11: 46400 | G11: 106 | H11: 98 | I11: 5 | J11: 29850 | O11: =V11*$O$2 -> 28.554101 | P11: =F11+J11+N11 -> 76250 | Q11: =P11/1000 -> 76.25 | R11: =MAX(Q11,O11) -> 76.25 | S11: =VLOOKUP(A11,[1]Index!$E:$M,8,) -> 56053.896 | T11: =S11-P11 -> -20196.104 | U11: =T11/S11 -> -0.36029795 | V11: =(((C11*D11*E11)+(G11*H11*I11)+(K11*L11*M11))/1000000)*35.32 -> 4.7590168 | W11: =Q11/V11 -> 16.022217 | X11: ok
A12: B-RVB-QN | B12: MB | C12: 207 | D12: 51 | E12: 8 | F12: 42600 | G12: 107 | H12: 80 | I12: 5 | J12: 54000 | O12: =V12*$O$2 -> 26.968092 | P12: =F12+J12+N12 -> 96600 | Q12: =P12/1000 -> 96.6 | R12: =MAX(Q12,O12) -> 96.6 | S12: =VLOOKUP(A12,[1]Index!$E:$M,8,) -> 61659.101 | T12: =S12-P12 -> -34940.899 | U12: =T12/S12 -> -0.56667869 | V12: =(((C12*D12*E12)+(G12*H12*I12)+(K12*L12*M12))/1000000)*35.32 -> 4.4946819 | W12: =Q12/V12 -> 21.492066 | X12: ok
A13: B-RVB-SN | B13: MB | C13: 120 | D13: 39 | E13: 8 | F13: 33000 | G13: 97 | H13: 56 | I13: 5 | J13: 14900 | O13: =V13*$O$2 -> 13.690032 | P13: =F13+J13+N13 -> 47900 | Q13: =P13/1000 -> 47.9 | R13: =MAX(Q13,O13) -> 47.9 | S13: =VLOOKUP(A13,[1]Index!$E:$M,8,) -> 41738.719 | T13: =S13-P13 -> -6161.2814 | U13: =T13/S13 -> -0.14761549 | V13: =(((C13*D13*E13)+(G13*H13*I13)+(K13*L13*M13))/1000000)*35.32 -> 2.281672 | W13: =Q13/V13 -> 20.993377 | X13: ok
A14: B-RVB-D36N | B14: SB | C14: 188 | D14: 44 | E14: 9 | F14: 37300 | O14: =V14*$O$2 -> 15.77702 | P14: =F14+J14+N14 -> 37300 | Q14: =P14/1000 -> 37.3 | R14: =MAX(Q14,O14) -> 37.3 | S14: =VLOOKUP(A14,[1]Index!$E:$M,8,) -> 34586.525 | T14: =S14-P14 -> -2713.4748 | U14: =T14/S14 -> -0.07845468 | V14: =(((C14*D14*E14)+(G14*H14*I14)+(K14*L14*M14))/1000000)*35.32 -> 2.6295034 | W14: =Q14/V14 -> 14.185188 | X14: ok
A15: BT-CO | B15: SB | C15: 74 | D15: 40 | E15: 6 | F15: 6600 | O15: =V15*$O$2 -> 3.7636992 | P15: =F15+J15+N15 -> 6600 | Q15: =P15/1000 -> 6.6 | R15: =MAX(Q15,O15) -> 6.6 | S15: =VLOOKUP(A15,[1]Index!$E:$M,8,) -> 6060.5378 | T15: =S15-P15 -> -539.46221 | U15: =T15/S15 -> -0.089012268 | V15: =(((C15*D15*E15)+(G15*H15*I15)+(K15*L15*M15))/1000000)*35.32 -> 0.6272832 | W15: =Q15/V15 -> 10.521563 | X15: ok
A16: BT-HE | B16: SB | C16: 42 | D16: 41 | E16: 6 | F16: 4780 | O16: =V16*$O$2 -> 2.1895574 | P16: =F16+J16+N16 -> 4780 | Q16: =P16/1000 -> 4.78 | R16: =MAX(Q16,O16) -> 4.78 | S16: =VLOOKUP(A16,[1]Index!$E:$M,8,) -> 4702.7014 | T16: =S16-P16 -> -77.298599 | U16: =T16/S16 -> -0.016437063 | V16: =(((C16*D16*E16)+(G16*H16*I16)+(K16*L16*M16))/1000000)*35.32 -> 0.36492624 | W16: =Q16/V16 -> 13.098537 | X16: ok
A17: BT-LE-B | B17: SB | C17: 64 | D17: 58 | E17: 12 | F17: 15000 | O17: =V17*$O$2 -> 9.4397645 | P17: =F17+J17+N17 -> 15000 | Q17: =P17/1000 -> 15 | R17: =MAX(Q17,O17) -> 15 | S17: =VLOOKUP(A17,[1]Index!$E:$M,8,) -> 8821.9178 | T17: =S17-P17 -> -6178.0822 | U17: =T17/S17 -> -0.70031056 | V17: =(((C17*D17*E17)+(G17*H17*I17)+(K17*L17*M17))/1000000)*35.32 -> 1.5732941 | W17: =Q17/V17 -> 9.5341362 | X17: phy. not avilable
A18: BT-OL | B18: SB | C18: 50 | D18: 45 | E18: 8 | F18: 8250 | O18: =V18*$O$2 -> 3.81456 | P18: =F18+J18+N18 -> 8250 | Q18: =P18/1000 -> 8.25 | R18: =MAX(Q18,O18) -> 8.25 | S18: =VLOOKUP(A18,[1]Index!$E:$M,8,) -> 8112 | T18: =S18-P18 -> -138 | U18: =T18/S18 -> -0.017011834 | V18: =(((C18*D18*E18)+(G18*H18*I18)+(K18*L18*M18))/1000000)*35.32 -> 0.63576 | W18: =Q18/V18 -> 12.976595 | X18: ok
A19: BT-OL-D | B19: SB | C19: 49 | D19: 43 | E19: 12 | F19: 10900 | O19: =V19*$O$2 -> 5.3581853 | P19: =F19+J19+N19 -> 10900 | Q19: =P19/1000 -> 10.9 | R19: =MAX(Q19,O19) -> 10.9 | S19: =VLOOKUP(A19,[1]Index!$E:$M,8,) -> 10252.116 | T19: =S19-P19 -> -647.88437 | U19: =T19/S19 -> -0.063195188 | V19: =(((C19*D19*E19)+(G19*H19*I19)+(K19*L19*M19))/1000000)*35.32 -> 0.89303088 | W19: =Q19/V19 -> 12.205625 | X19: ok
A20: CT-ATD-LA | B20: SB | C20: 123 | D20: 56 | E20: 5 | F20: 24490 | O20: =V20*$O$2 -> 7.2985248 | P20: =F20+J20+N20 -> 24490 | Q20: =P20/1000 -> 24.49 | R20: =MAX(Q20,O20) -> 24.49 | S20: =VLOOKUP(A20,[1]Index!$E:$M,8,) -> 23784.664 | T20: =S20-P20 -> -705.33643 | U20: =T20/S20 -> -0.029655094 | V20: =(((C20*D20*E20)+(G20*H20*I20)+(K20*L20*M20))/1000000)*35.32 -> 1.2164208 | W20: =Q20/V20 -> 20.132836 | X20: phy. not avilable
A21: CT-ATD-ST | B21: SB | C21: 96 | D21: 44 | E21: 8 | F21: 11100 | O21: =V21*$O$2 -> 7.1612006 | P21: =F21+J21+N21 -> 11100 | Q21: =P21/1000 -> 11.1 | R21: =MAX(Q21,O21) -> 11.1 | S21: =VLOOKUP(A21,[1]Index!$E:$M,8,) -> 13438.902 | T21: =S21-P21 -> 2338.9017 | U21: =T21/S21 -> 0.17403964 | V21: =(((C21*D21*E21)+(G21*H21*I21)+(K21*L21*M21))/1000000)*35.32 -> 1.1935334 | W21: =Q21/V21 -> 9.3001165 | X21: ok
A22: CT-DOV | B22: SB | C22: 111 | D22: 54 | E22: 8 | F22: 23800 | O22: =V22*$O$2 -> 10.161988 | P22: =F22+J22+N22 -> 23800 | Q22: =P22/1000 -> 23.8 | R22: =MAX(Q22,O22) -> 23.8 | S22: =VLOOKUP(A22,[1]Index!$E:$M,8,) -> 21457 | T22: =S22-P22 -> -2343 | U22: =T22/S22 -> -0.10919513 | V22: =(((C22*D22*E22)+(G22*H22*I22)+(K22*L22*M22))/1000000)*35.32 -> 1.6936646 | W22: =Q22/V22 -> 14.052369 | X22: ok
A23: CT-GSE-RT | B23: SB | C23: 100 | D23: 50 | E23: 4 | F23: 7100 | O23: =V23*$O$2 -> 4.2384 | P23: =F23+J23+N23 -> 7100 | Q23: =P23/1000 -> 7.1 | R23: =MAX(Q23,O23) -> 7.1 | S23: =VLOOKUP(A23,[1]Index!$E:$M,8,) -> 5381.721 | T23: =S23-P23 -> -1718.279 | U23: =T23/S23 -> -0.31928059 | V23: =(((C23*D23*E23)+(G23*H23*I23)+(K23*L23*M23))/1000000)*35.32 -> 0.7064 | W23: =Q23/V23 -> 10.050963 | X23: ok
A24: CT-GSE-RT2 | B24: SB | C24: 100 | D24: 50 | E24: 4 | F24: 11550 | O24: =V24*$O$2 -> 4.2384 | P24: =F24+J24+N24 -> 11550 | Q24: =P24/1000 -> 11.55 | R24: =MAX(Q24,O24) -> 11.55 | S24: =VLOOKUP(A24,[1]Index!$E:$M,8,) -> 9982.928 | T24: =S24-P24 -> -1567.072 | U24: =T24/S24 -> -0.15697519 | V24: =(((C24*D24*E24)+(G24*H24*I24)+(K24*L24*M24))/1000000)*35.32 -> 0.7064 | W24: =Q24/V24 -> 16.35051 | X24: ok
A25: CT-GSE-SQ | B25: SB | C25: 77 | D25: 77 | E25: 4 | F25: 8050 | O25: =V25*$O$2 -> 5.0258947 | P25: =F25+J25+N25 -> 8050 | Q25: =P25/1000 -> 8.05 | R25: =MAX(Q25,O25) -> 8.05 | S25: =VLOOKUP(A25,[1]Index!$E:$M,8,) -> 6253.372 | T25: =S25-P25 -> -1796.628 | U25: =T25/S25 -> -0.28730546 | V25: =(((C25*D25*E25)+(G25*H25*I25)+(K25*L25*M25))/1000000)*35.32 -> 0.83764912 | W25: =Q25/V25 -> 9.6102292 | X25: ok
... A31: CT-MD-SQ | B31: SB | C31: 85 | D31: 84 | E31: 6 | F31: 17400 | O31: =V31*$O$2 -> 9.0786528 | P31: =F31+J31+N31 -> 17400 | Q31: =P31/1000 -> 17.4 | R31: =MAX(Q31,O31) -> 17.4 | S31: =VLOOKUP(A31,[1]Index!$E:$M,8,) -> 18992.418 | T31: =S31-P31 -> 1592.4179 | U31: =T31/S31 -> 0.083844927 | V31: =(((C31*D31*E31)+(G31*H31*I31)+(K31*L31*M31))/1000000)*35.32 -> 1.5131088 | W31: =Q31/V31 -> 11.499504 | X31: phy. not avilable
A32: CT-MT-RO | B32: MB | C32: 70 | D32: 68 | E32: 3 | F32: 4300 | G32: 51 | H32: 12 | I32: 10 | J32: 1500 | O32: =V32*$O$2 -> 4.323168 | P32: =F32+J32+N32 -> 5800 | Q32: =P32/1000 -> 5.8 | R32: =MAX(Q32,O32) -> 5.8 | S32: =VLOOKUP(A32,[1]Index!$E:$M,8,) -> 4517.919 | T32: =S32-P32 -> -1282.081 | U32: =T32/S32 -> -0.28377689 | V32: =(((C32*D32*E32)+(G32*H32*I32)+(K32*L32*M32))/1000000)*35.32 -> 0.720528 | W32: =Q32/V32 -> 8.0496525 | X32: ok
A33: CT-MT-RT | B33: MB | C33: 86 | D33: 46 | E33: 5 | F33: 4700 | G33: 51 | H33: 12 | I33: 10 | J33: 1500 | O33: =V33*$O$2 -> 5.488728 | P33: =F33+J33+N33 -> 6200 | Q33: =P33/1000 -> 6.2 | R33: =MAX(Q33,O33) -> 6.2 | S33: =VLOOKUP(A33,[1]Index!$E:$M,8,) -> 3843.3503 | T33: =S33-P33 -> -2356.6497 | U33: =T33/S33 -> -0.61317587 | V33: =(((C33*D33*E33)+(G33*H33*I33)+(K33*L33*M33))/1000000)*35.32 -> 0.914788 | W33: =Q33/V33 -> 6.7775266 | X33: ok
A34: CT-MT-SQ | B34: MB | C34: 100 | D34: 50 | E34: 4 | F34: 8900 | G34: 51 | H34: 12 | I34: 10 | J34: 1500 | O34: =V34*$O$2 -> 5.5353504 | P34: =F34+J34+N34 -> 10400 | Q34: =P34/1000 -> 10.4 | R34: =MAX(Q34,O34) -> 10.4 | S34: =VLOOKUP(A34,[1]Index!$E:$M,8,) -> 5208.6044 | T34: =S34-P34 -> -5191.3956 | U34: =T34/S34 -> -0.99669607 | V34: =(((C34*D34*E34)+(G34*H34*I34)+(K34*L34*M34))/1000000)*35.32 -> 0.9225584 | W34: =Q34/V34 -> 11.272999 | X34: Ok
A35: CT-NO-RT | B35: SB | C35: 85 | D35: 45 | E35: 6 | F35: 10700 | G35: 51 | H35: 12 | I35: 10 | J35: 1500 | O35: =V35*$O$2 -> 6.1605144 | P35: =F35+J35+N35 -> 12200 | Q35: =P35/1000 -> 12.2 | R35: =MAX(Q35,O35) -> 12.2 | S35: =VLOOKUP(A35,[1]Index!$E:$M,8,) -> 10756.616 | T35: =S35-P35 -> -1443.3841 | U35: =T35/S35 -> -0.1341857 | V35: =(((C35*D35*E35)+(G35*H35*I35)+(K35*L35*M35))/1000000)*35.32 -> 1.0267524 | W35: =Q35/V35 -> 11.882125 | X35: Ok
A36: CT-NO-SQ | B36: SB | C36: 76 | D36: 76 | E36: 6 | F36: 13560 | O36: =V36*$O$2 -> 7.3442995 | P36: =F36+J36+N36 -> 13560 | Q36: =P36/1000 -> 13.56 | R36: =MAX(Q36,O36) -> 13.56 | S36: =VLOOKUP(A36,[1]Index!$E:$M,8,) -> 14621.767 | T36: =S36-P36 -> 1061.7672 | U36: =T36/S36 -> 0.07261552 | V36: =(((C36*D36*E36)+(G36*H36*I36)+(K36*L36*M36))/1000000)*35.32 -> 1.2240499 | W36: =Q36/V36 -> 11.07798 | X36: Ok
A37: CT-OL | B37: SB | C37: 85 | D37: 48 | E37: 8 | F37: 11500 | O37: =V37*$O$2 -> 6.9170688 | P37: =F37+J37+N37 -> 11500 | Q37: =P37/1000 -> 11.5 | R37: =MAX(Q37,O37) -> 11.5 | S37: =VLOOKUP(A37,[1]Index!$E:$M,8,) -> 11287.169 | T37: =S37-P37 -> -212.8311 | U37: =T37/S37 -> -0.018856021 | V37: =(((C37*D37*E37)+(G37*H37*I37)+(K37*L37*M37))/1000000)*35.32 -> 1.1528448 | W37: =Q37/V37 -> 9.9753237 | X37: phy. not avilable
A38: CT-OSN-OV | B38: SB | C38: 105 | D38: 65 | E38: 4 | F38: 96400 | O38: =V38*$O$2 -> 5.785416 | P38: =F38+J38+N38 -> 96400 | Q38: =P38/1000 -> 96.4 | R38: =MAX(Q38,O38) -> 96.4 | S38: =VLOOKUP(A38,[1]Index!$E:$M,8,) -> 8466.6325 | T38: =S38-P38 -> -87933.367 | U38: =T38/S38 -> -10.385873 | V38: =(((C38*D38*E38)+(G38*H38*I38)+(K38*L38*M38))/1000000)*35.32 -> 0.964236 | W38: =Q38/V38 -> 99.975525 | X38: phy. not avilable
A39: CT-OSN-RT | B39: SB | C39: 100 | D39: 50 | E39: 5 | F39: 8800 | O39: =V39*$O$2 -> 5.298 | P39: =F39+J39+N39 -> 8800 | Q39: =P39/1000 -> 8.8 | R39: =MAX(Q39,O39) -> 8.8 | S39: =VLOOKUP(A39,[1]Index!$E:$M,8,) -> 8494.1627 | T39: =S39-P39 -> -305.83728 | U39: =T39/S39 -> -0.036005582 | V39: =(((C39*D39*E39)+(G39*H39*I39)+(K39*L39*M39))/1000000)*35.32 -> 0.883 | W39: =Q39/V39 -> 9.9660249 | X39: phy. not avilable
A40: CT-SY | B40: SB | C40: 79 | D40: 66 | E40: 8 | F40: 11800 | O40: =V40*$O$2 -> 8.839607 | P40: =F40+J40+N40 -> 11800 | Q40: =P40/1000 -> 11.8 | R40: =MAX(Q40,O40) -> 11.8 | S40: =VLOOKUP(A40,[1]Index!$E:$M,8,) -> 11447.544 | T40: =S40-P40 -> -352.45617 | U40: =T40/S40 -> -0.030788803 | V40: =(((C40*D40*E40)+(G40*H40*I40)+(K40*L40*M40))/1000000)*35.32 -> 1.4732678 | W40: =Q40/V40 -> 8.0094058 | X40: Ok
A41: CT-TR-RT | B41: SB | C41: 97 | D41: 45 | E41: 8 | F41: 12200 | O41: =V41*$O$2 -> 7.4002464 | P41: =F41+J41+N41 -> 12200 | Q41: =P41/1000 -> 12.2 | R41: =MAX(Q41,O41) -> 12.2 | S41: =VLOOKUP(A41,[1]Index!$E:$M,8,) -> 12000 | T41: =S41-P41 -> -200 | U41: =T41/S41 -> -0.016666667 | V41: =(((C41*D41*E41)+(G41*H41*I41)+(K41*L41*M41))/1000000)*35.32 -> 1.2333744 | W41: =Q41/V41 -> 9.8915625 | X41: phy. not avilable
A42: CT-TR-RTS | B42: SB | C42: 110 | D42: 50 | E42: 5 | F42: 12750 | O42: =V42*$O$2 -> 5.8278 | P42: =F42+J42+N42 -> 12750 | Q42: =P42/1000 -> 12.75 | R42: =MAX(Q42,O42) -> 12.75 | S42: =VLOOKUP(A42,[1]Index!$E:$M,8,) -> 13032.699 | T42: =S42-P42 -> 282.69902 | U42: =T42/S42 -> 0.021691518 | V42: =(((C42*D42*E42)+(G42*H42*I42)+(K42*L42*M42))/1000000)*35.32 -> 0.9713 | W42: =Q42/V42 -> 13.126737 | X42: phy. not avilable
A43: CT-VC | B43: SB | C43: 88 | D43: 45 | E43: 9 | F43: 15400 | O43: =V43*$O$2 -> 7.5528288 | P43: =F43+J43+N43 -> 15400 | Q43: =P43/1000 -> 15.4 | R43: =MAX(Q43,O43) -> 15.4 | S43: =VLOOKUP(A43,[1]Index!$E:$M,8,) -> 15171.843 | T43: =S43-P43 -> -228.15658 | U43: =T43/S43 -> -0.015038158 | V43: =(((C43*D43*E43)+(G43*H43*I43)+(K43*L43*M43))/1000000)*35.32 -> 1.2588048 | W43: =Q43/V43 -> 12.233827 | X43: Ok
A44: DT-GRA | B44: SB | C44: 67 | D44: 40 | E44: 4 | F44: 5350 | O44: =V44*$O$2 -> 2.2717824 | P44: =F44+J44+N44 -> 5350 | Q44: =P44/1000 -> 5.35 | R44: =MAX(Q44,O44) -> 5.35 | S44: =VLOOKUP(A44,[1]Index!$E:$M,8,) -> 6383.7606 | T44: =S44-P44 -> 1033.7606 | U44: =T44/S44 -> 0.16193599 | V44: =(((C44*D44*E44)+(G44*H44*I44)+(K44*L44*M44))/1000000)*35.32 -> 0.3786304 | W44: =Q44/V44 -> 14.129874 | X44: phy. not avilable
A45: DT-HE-3 | B45: SB | C45: 85 | D45: 85 | E45: 5 | F45: 9920 | O45: =V45*$O$2 -> 7.65561 | P45: =F45+J45+N45 -> 9920 | Q45: =P45/1000 -> 9.92 | R45: =MAX(Q45,O45) -> 9.92 | S45: =VLOOKUP(A45,[1]Index!$E:$M,8,) -> 10388.342 | T45: =S45-P45 -> 468.34195 | U45: =T45/S45 -> 0.045083417 | V45: =(((C45*D45*E45)+(G45*H45*I45)+(K45*L45*M45))/1000000)*35.32 -> 1.275935 | W45: =Q45/V45 -> 7.7746907 | X45: phy. not avilable
...

Sheet Audit VAR
A1: MANUAL ENTRIES HERE | C1: Box 1 Dimension Details | G1: Box 2 Dimension Details | K1: Box 3 Dimension Details | O1: Total Weight
C2: Long | D2: Med | E2: Smal | F2: Actual.Wht | G2: Long | H2: Med | I2: Smal | J2: Actual.Wht | K2: Long | L2: Med | M2: Smal | N2: Actual.Wht | O2: Actual.Wht | P2: Wht(Kgs) | Q2: CBN | R2: KG/CBN
A3: MTP SKU Code | B3: SB/MB | C3: Lcm | D3: Bcm | E3: Hcm | F3: PW(gm) | G3: Lcm | H3: Bcm | I3: Hcm | J3: PW(gm) | K3: Lcm | L3: Bcm | M3: Hcm | N3: PW(gm) | O3: Gms | P3: Kgs
A4: B-MLT-KT | B4: =VLOOKUP(A4,'Billing Dimensions'!A:B,2,FALSE) -> MB | C4: =VLOOKUP(A4,'Billing Dimensions'!$A:$N,3,FALSE)-VLOOKUP(A4,'Audit Dimensions'!$A:$N,3,FALSE) -> 1 | D4: =VLOOKUP(A4,'Billing Dimensions'!$A:$N,4,FALSE)-VLOOKUP(A4,'Audit Dimensions'!$A:$N,4,FALSE) -> 0 | E4: =VLOOKUP(A4,'Billing Dimensions'!$A:$N,5,FALSE)-VLOOKUP(A4,'Audit Dimensions'!$A:$N,5,FALSE) -> -1 | F4: =VLOOKUP(A4,'Billing Dimensions'!$A:$N,6,FALSE)-VLOOKUP(A4,'Audit Dimensions'!$A:$N,6,FALSE) -> -150 | G4: =VLOOKUP(A4,'Billing Dimensions'!$A:$N,7,FALSE)-VLOOKUP(A4,'Audit Dimensions'!$A:$N,7,FALSE) -> -4 | H4: =VLOOKUP(A4,'Billing Dimensions'!$A:$N,8,FALSE)-VLOOKUP(A4,'Audit Dimensions'!$A:$N,8,FALSE) -> 0 | I4: =VLOOKUP(A4,'Billing Dimensions'!$A:$N,9,FALSE)-VLOOKUP(A4,'Audit Dimensions'!$A:$N,9,FALSE) -> 1 | J4: =VLOOKUP(A4,'Billing Dimensions'!$A:$N,10,FALSE)-VLOOKUP(A4,'Audit Dimensions'!$A:$N,10,FALSE) -> -900 | K4: =VLOOKUP(A4,'Billing Dimensions'!$A:$N,11,FALSE)-VLOOKUP(A4,'Audit Dimensions'!$A:$N,11,FALSE) -> 5 | L4: =VLOOKUP(A4,'Billing Dimensions'!$A:$N,12,FALSE)-VLOOKUP(A4,'Audit Dimensions'!$A:$N,12,FALSE) -> 3 | M4: =VLOOKUP(A4,'Billing Dimensions'!$A:$N,13,FALSE)-VLOOKUP(A4,'Audit Dimensions'!$A:$N,13,FALSE) -> 1 | N4: =VLOOKUP(A4,'Billing Dimensions'!$A:$N,14,FALSE)-VLOOKUP(A4,'Audit Dimensions'!$A:$N,14,FALSE) -> 1650 | O4: =VLOOKUP(A4,'Billing Dimensions'!A:Q,16,FALSE)-VLOOKUP('Audit VAR'!A4,'Audit Dimensions'!A:P,16,FALSE) -> 600 | P4: =O4/1000 -> 0.6 | Q4: =(((C4*D4*E4)+(G4*H4*I4)+(K4*L4*M4))/1000000)*35.32 -> 0.0005298 | R4: =P4/Q4 -> 1132.5028
A5: B-MLT-QT | B5: =VLOOKUP(A5,'Billing Dimensions'!A:B,2,FALSE) -> MB | C5: =VLOOKUP(A5,'Billing Dimensions'!$A:$N,3,FALSE)-VLOOKUP(A5,'Audit Dimensions'!$A:$N,3,FALSE) -> -1 | D5: =VLOOKUP(A5,'Billing Dimensions'!$A:$N,4,FALSE)-VLOOKUP(A5,'Audit Dimensions'!$A:$N,4,FALSE) -> -1 | E5: =VLOOKUP(A5,'Billing Dimensions'!$A:$N,5,FALSE)-VLOOKUP(A5,'Audit Dimensions'!$A:$N,5,FALSE) -> 0 | F5: =VLOOKUP(A5,'Billing Dimensions'!$A:$N,6,FALSE)-VLOOKUP(A5,'Audit Dimensions'!$A:$N,6,FALSE) -> -1480 | G5: =VLOOKUP(A5,'Billing Dimensions'!$A:$N,7,FALSE)-VLOOKUP(A5,'Audit Dimensions'!$A:$N,7,FALSE) -> -2 | H5: =VLOOKUP(A5,'Billing Dimensions'!$A:$N,8,FALSE)-VLOOKUP(A5,'Audit Dimensions'!$A:$N,8,FALSE) -> 18 | I5: =VLOOKUP(A5,'Billing Dimensions'!$A:$N,9,FALSE)-VLOOKUP(A5,'Audit Dimensions'!$A:$N,9,FALSE) -> 1 | J5: =VLOOKUP(A5,'Billing Dimensions'!$A:$N,10,FALSE)-VLOOKUP(A5,'Audit Dimensions'!$A:$N,10,FALSE) -> 4700 | K5: =VLOOKUP(A5,'Billing Dimensions'!$A:$N,11,FALSE)-VLOOKUP(A5,'Audit Dimensions'!$A:$N,11,FALSE) -> 2 | L5: =VLOOKUP(A5,'Billing Dimensions'!$A:$N,12,FALSE)-VLOOKUP(A5,'Audit Dimensions'!$A:$N,12,FALSE) -> 1 | M5: =VLOOKUP(A5,'Billing Dimensions'!$A:$N,13,FALSE)-VLOOKUP(A5,'Audit Dimensions'!$A:$N,13,FALSE) -> 1 | N5: =VLOOKUP(A5,'Billing Dimensions'!$A:$N,14,FALSE)-VLOOKUP(A5,'Audit Dimensions'!$A:$N,14,FALSE) -> -2750 | O5: =VLOOKUP(A5,'Billing Dimensions'!A:Q,16,FALSE)-VLOOKUP('Audit VAR'!A5,'Audit Dimensions'!A:P,16,FALSE) -> 470 | P5: =O5/1000 -> 0.47 | Q5: =(((C5*D5*E5)+(G5*H5*I5)+(K5*L5*M5))/1000000)*35.32 -> -0.00120088 | R5: =P5/Q5 -> -391.37965
A6: B-POL-KN | B6: =VLOOKUP(A6,'Billing Dimensions'!A:B,2,FALSE) -> MB | C6: =VLOOKUP(A6,'Billing Dimensions'!$A:$N,3,FALSE)-VLOOKUP(A6,'Audit Dimensions'!$A:$N,3,FALSE) -> 205 | D6: =VLOOKUP(A6,'Billing Dimensions'!$A:$N,4,FALSE)-VLOOKUP(A6,'Audit Dimensions'!$A:$N,4,FALSE) -> 54 | E6: =VLOOKUP(A6,'Billing Dimensions'!$A:$N,5,FALSE)-VLOOKUP(A6,'Audit Dimensions'!$A:$N,5,FALSE) -> 10 | F6: =VLOOKUP(A6,'Billing Dimensions'!$A:$N,6,FALSE)-VLOOKUP(A6,'Audit Dimensions'!$A:$N,6,FALSE) -> 35000 | G6: =VLOOKUP(A6,'Billing Dimensions'!$A:$N,7,FALSE)-VLOOKUP(A6,'Audit Dimensions'!$A:$N,7,FALSE) -> 105 | H6: =VLOOKUP(A6,'Billing Dimensions'!$A:$N,8,FALSE)-VLOOKUP(A6,'Audit Dimensions'!$A:$N,8,FALSE) -> 94 | I6: =VLOOKUP(A6,'Billing Dimensions'!$A:$N,9,FALSE)-VLOOKUP(A6,'Audit Dimensions'!$A:$N,9,FALSE) -> 5 | J6: =VLOOKUP(A6,'Billing Dimensions'!$A:$N,10,FALSE)-VLOOKUP(A6,'Audit Dimensions'!$A:$N,10,FALSE) -> 35000 | K6: =VLOOKUP(A6,'Billing Dimensions'!$A:$N,11,FALSE)-VLOOKUP(A6,'Audit Dimensions'!$A:$N,11,FALSE) -> 0 | L6: =VLOOKUP(A6,'Billing Dimensions'!$A:$N,12,FALSE)-VLOOKUP(A6,'Audit Dimensions'!$A:$N,12,FALSE) -> 0 | M6: =VLOOKUP(A6,'Billing Dimensions'!$A:$N,13,FALSE)-VLOOKUP(A6,'Audit Dimensions'!$A:$N,13,FALSE) -> 0 | N6: =VLOOKUP(A6,'Billing Dimensions'!$A:$N,14,FALSE)-VLOOKUP(A6,'Audit Dimensions'!$A:$N,14,FALSE) -> 0 | O6: =VLOOKUP(A6,'Billing Dimensions'!A:Q,16,FALSE)-VLOOKUP('Audit VAR'!A6,'Audit Dimensions'!A:P,16,FALSE) -> 70000 | P6: =O6/1000 -> 70 | Q6: =(((C6*D6*E6)+(G6*H6*I6)+(K6*L6*M6))/1000000)*35.32 -> 5.652966 | R6: =P6/Q6 -> 12.38288
A7: B-POL-KT | B7: =VLOOKUP(A7,'Billing Dimensions'!A:B,2,FALSE) -> MB | C7: =VLOOKUP(A7,'Billing Dimensions'!$A:$N,3,FALSE)-VLOOKUP(A7,'Audit Dimensions'!$A:$N,3,FALSE) -> 1 | D7: =VLOOKUP(A7,'Billing Dimensions'!$A:$N,4,FALSE)-VLOOKUP(A7,'Audit Dimensions'!$A:$N,4,FALSE) -> -2 | E7: =VLOOKUP(A7,'Billing Dimensions'!$A:$N,5,FALSE)-VLOOKUP(A7,'Audit Dimensions'!$A:$N,5,FALSE) -> 1 | F7: =VLOOKUP(A7,'Billing Dimensions'!$A:$N,6,FALSE)-VLOOKUP(A7,'Audit Dimensions'!$A:$N,6,FALSE) -> -1300 | G7: =VLOOKUP(A7,'Billing Dimensions'!$A:$N,7,FALSE)-VLOOKUP(A7,'Audit Dimensions'!$A:$N,7,FALSE) -> 43 | H7: =VLOOKUP(A7,'Billing Dimensions'!$A:$N,8,FALSE)-VLOOKUP(A7,'Audit Dimensions'!$A:$N,8,FALSE) -> 0 | I7: =VLOOKUP(A7,'Billing Dimensions'!$A:$N,9,FALSE)-VLOOKUP(A7,'Audit Dimensions'!$A:$N,9,FALSE) -> 0 | J7: =VLOOKUP(A7,'Billing Dimensions'!$A:$N,10,FALSE)-VLOOKUP(A7,'Audit Dimensions'!$A:$N,10,FALSE) -> -900 | K7: =VLOOKUP(A7,'Billing Dimensions'!$A:$N,11,FALSE)-VLOOKUP(A7,'Audit Dimensions'!$A:$N,11,FALSE) -> 1 | L7: =VLOOKUP(A7,'Billing Dimensions'!$A:$N,12,FALSE)-VLOOKUP(A7,'Audit Dimensions'!$A:$N,12,FALSE) -> 17 | M7: =VLOOKUP(A7,'Billing Dimensions'!$A:$N,13,FALSE)-VLOOKUP(A7,'Audit Dimensions'!$A:$N,13,FALSE) -> 0 | N7: =VLOOKUP(A7,'Billing Dimensions'!$A:$N,14,FALSE)-VLOOKUP(A7,'Audit Dimensions'!$A:$N,14,FALSE) -> 1340 | O7: =VLOOKUP(A7,'Billing Dimensions'!A:Q,16,FALSE)-VLOOKUP('Audit VAR'!A7,'Audit Dimensions'!A:P,16,FALSE) -> -860 | P7: =O7/1000 -> -0.86 | Q7: =(((C7*D7*E7)+(G7*H7*I7)+(K7*L7*M7))/1000000)*35.32 -> -7.064e-05 | R7: =P7/Q7 -> 12174.405
A8: B-POL-QN | B8: =VLOOKUP(A8,'Billing Dimensions'!A:B,2,FALSE) -> MB | C8: =VLOOKUP(A8,'Billing Dimensions'!$A:$N,3,FALSE)-VLOOKUP(A8,'Audit Dimensions'!$A:$N,3,FALSE) -> 206 | D8: =VLOOKUP(A8,'Billing Dimensions'!$A:$N,4,FALSE)-VLOOKUP(A8,'Audit Dimensions'!$A:$N,4,FALSE) -> 50 | E8: =VLOOKUP(A8,'Billing Dimensions'!$A:$N,5,FALSE)-VLOOKUP(A8,'Audit Dimensions'!$A:$N,5,FALSE) -> 10 | F8: =VLOOKUP(A8,'Billing Dimensions'!$A:$N,6,FALSE)-VLOOKUP(A8,'Audit Dimensions'!$A:$N,6,FALSE) -> 46000 | G8: =VLOOKUP(A8,'Billing Dimensions'!$A:$N,7,FALSE)-VLOOKUP(A8,'Audit Dimensions'!$A:$N,7,FALSE) -> 102 | H8: =VLOOKUP(A8,'Billing Dimensions'!$A:$N,8,FALSE)-VLOOKUP(A8,'Audit Dimensions'!$A:$N,8,FALSE) -> 79 | I8: =VLOOKUP(A8,'Billing Dimensions'!$A:$N,9,FALSE)-VLOOKUP(A8,'Audit Dimensions'!$A:$N,9,FALSE) -> 5 | J8: =VLOOKUP(A8,'Billing Dimensions'!$A:$N,10,FALSE)-VLOOKUP(A8,'Audit Dimensions'!$A:$N,10,FALSE) -> 24000 | K8: =VLOOKUP(A8,'Billing Dimensions'!$A:$N,11,FALSE)-VLOOKUP(A8,'Audit Dimensions'!$A:$N,11,FALSE) -> 0 | L8: =VLOOKUP(A8,'Billing Dimensions'!$A:$N,12,FALSE)-VLOOKUP(A8,'Audit Dimensions'!$A:$N,12,FALSE) -> 0 | M8: =VLOOKUP(A8,'Billing Dimensions'!$A:$N,13,FALSE)-VLOOKUP(A8,'Audit Dimensions'!$A:$N,13,FALSE) -> 0 | N8: =VLOOKUP(A8,'Billing Dimensions'!$A:$N,14,FALSE)-VLOOKUP(A8,'Audit Dimensions'!$A:$N,14,FALSE) -> 0 | O8: =VLOOKUP(A8,'Billing Dimensions'!A:Q,16,FALSE)-VLOOKUP('Audit VAR'!A8,'Audit Dimensions'!A:P,16,FALSE) -> 70000 | P8: =O8/1000 -> 70 | Q8: =(((C8*D8*E8)+(G8*H8*I8)+(K8*L8*M8))/1000000)*35.32 -> 5.0610028 | R8: =P8/Q8 -> 13.831251
A9: B-POL-QT | B9: =VLOOKUP(A9,'Billing Dimensions'!A:B,2,FALSE) -> MB | C9: =VLOOKUP(A9,'Billing Dimensions'!$A:$N,3,FALSE)-VLOOKUP(A9,'Audit Dimensions'!$A:$N,3,FALSE) -> -6 | D9: =VLOOKUP(A9,'Billing Dimensions'!$A:$N,4,FALSE)-VLOOKUP(A9,'Audit Dimensions'!$A:$N,4,FALSE) -> -9 | E9: =VLOOKUP(A9,'Billing Dimensions'!$A:$N,5,FALSE)-VLOOKUP(A9,'Audit Dimensions'!$A:$N,5,FALSE) -> 2 | F9: =VLOOKUP(A9,'Billing Dimensions'!$A:$N,6,FALSE)-VLOOKUP(A9,'Audit Dimensions'!$A:$N,6,FALSE) -> 490 | G9: =VLOOKUP(A9,'Billing Dimensions'!$A:$N,7,FALSE)-VLOOKUP(A9,'Audit Dimensions'!$A:$N,7,FALSE) -> -1 | H9: =VLOOKUP(A9,'Billing Dimensions'!$A:$N,8,FALSE)-VLOOKUP(A9,'Audit Dimensions'!$A:$N,8,FALSE) -> 0 | I9: =VLOOKUP(A9,'Billing Dimensions'!$A:$N,9,FALSE)-VLOOKUP(A9,'Audit Dimensions'!$A:$N,9,FALSE) -> 0 | J9: =VLOOKUP(A9,'Billing Dimensions'!$A:$N,10,FALSE)-VLOOKUP(A9,'Audit Dimensions'!$A:$N,10,FALSE) -> -1750 | K9: =VLOOKUP(A9,'Billing Dimensions'!$A:$N,11,FALSE)-VLOOKUP(A9,'Audit Dimensions'!$A:$N,11,FALSE) -> 3 | L9: =VLOOKUP(A9,'Billing Dimensions'!$A:$N,12,FALSE)-VLOOKUP(A9,'Audit Dimensions'!$A:$N,12,FALSE) -> 2 | M9: =VLOOKUP(A9,'Billing Dimensions'!$A:$N,13,FALSE)-VLOOKUP(A9,'Audit Dimensions'!$A:$N,13,FALSE) -> 1 | N9: =VLOOKUP(A9,'Billing Dimensions'!$A:$N,14,FALSE)-VLOOKUP(A9,'Audit Dimensions'!$A:$N,14,FALSE) -> 400 | O9: =VLOOKUP(A9,'Billing Dimensions'!A:Q,16,FALSE)-VLOOKUP('Audit VAR'!A9,'Audit Dimensions'!A:P,16,FALSE) -> -860 | P9: =O9/1000 -> -0.86 | Q9: =(((C9*D9*E9)+(G9*H9*I9)+(K9*L9*M9))/1000000)*35.32 -> 0.00402648 | R9: =P9/Q9 -> -213.58606
A10: B-POL-SN | B10: =VLOOKUP(A10,'Billing Dimensions'!A:B,2,FALSE) -> MB | C10: =VLOOKUP(A10,'Billing Dimensions'!$A:$N,3,FALSE)-VLOOKUP(A10,'Audit Dimensions'!$A:$N,3,FALSE) -> -2 | D10: =VLOOKUP(A10,'Billing Dimensions'!$A:$N,4,FALSE)-VLOOKUP(A10,'Audit Dimensions'!$A:$N,4,FALSE) -> 0 | E10: =VLOOKUP(A10,'Billing Dimensions'!$A:$N,5,FALSE)-VLOOKUP(A10,'Audit Dimensions'!$A:$N,5,FALSE) -> 0 | F10: =VLOOKUP(A10,'Billing Dimensions'!$A:$N,6,FALSE)-VLOOKUP(A10,'Audit Dimensions'!$A:$N,6,FALSE) -> -2550 | G10: =VLOOKUP(A10,'Billing Dimensions'!$A:$N,7,FALSE)-VLOOKUP(A10,'Audit Dimensions'!$A:$N,7,FALSE) -> 1 | H10: =VLOOKUP(A10,'Billing Dimensions'!$A:$N,8,FALSE)-VLOOKUP(A10,'Audit Dimensions'!$A:$N,8,FALSE) -> -1 | I10: =VLOOKUP(A10,'Billing Dimensions'!$A:$N,9,FALSE)-VLOOKUP(A10,'Audit Dimensions'!$A:$N,9,FALSE) -> 0 | J10: =VLOOKUP(A10,'Billing Dimensions'!$A:$N,10,FALSE)-VLOOKUP(A10,'Audit Dimensions'!$A:$N,10,FALSE) -> 300 | K10: =VLOOKUP(A10,'Billing Dimensions'!$A:$N,11,FALSE)-VLOOKUP(A10,'Audit Dimensions'!$A:$N,11,FALSE) -> 0 | L10: =VLOOKUP(A10,'Billing Dimensions'!$A:$N,12,FALSE)-VLOOKUP(A10,'Audit Dimensions'!$A:$N,12,FALSE) -> 0 | M10: =VLOOKUP(A10,'Billing Dimensions'!$A:$N,13,FALSE)-VLOOKUP(A10,'Audit Dimensions'!$A:$N,13,FALSE) -> 0 | N10: =VLOOKUP(A10,'Billing Dimensions'!$A:$N,14,FALSE)-VLOOKUP(A10,'Audit Dimensions'!$A:$N,14,FALSE) -> 0 | O10: =VLOOKUP(A10,'Billing Dimensions'!A:Q,16,FALSE)-VLOOKUP('Audit VAR'!A10,'Audit Dimensions'!A:P,16,FALSE) -> -2250 | P10: =O10/1000 -> -2.25 | Q10: =(((C10*D10*E10)+(G10*H10*I10)+(K10*L10*M10))/1000000)*35.32 -> 0 | R10: =P10/Q10 -> #DIV/0!
A11: B-RVB-KN | B11: =VLOOKUP(A11,'Billing Dimensions'!A:B,2,FALSE) -> MB | C11: =VLOOKUP(A11,'Billing Dimensions'!$A:$N,3,FALSE)-VLOOKUP(A11,'Audit Dimensions'!$A:$N,3,FALSE) -> -1 | D11: =VLOOKUP(A11,'Billing Dimensions'!$A:$N,4,FALSE)-VLOOKUP(A11,'Audit Dimensions'!$A:$N,4,FALSE) -> 0 | E11: =VLOOKUP(A11,'Billing Dimensions'!$A:$N,5,FALSE)-VLOOKUP(A11,'Audit Dimensions'!$A:$N,5,FALSE) -> 0 | F11: =VLOOKUP(A11,'Billing Dimensions'!$A:$N,6,FALSE)-VLOOKUP(A11,'Audit Dimensions'!$A:$N,6,FALSE) -> -800 | G11: =VLOOKUP(A11,'Billing Dimensions'!$A:$N,7,FALSE)-VLOOKUP(A11,'Audit Dimensions'!$A:$N,7,FALSE) -> -1 | H11: =VLOOKUP(A11,'Billing Dimensions'!$A:$N,8,FALSE)-VLOOKUP(A11,'Audit Dimensions'!$A:$N,8,FALSE) -> -2 | I11: =VLOOKUP(A11,'Billing Dimensions'!$A:$N,9,FALSE)-VLOOKUP(A11,'Audit Dimensions'!$A:$N,9,FALSE) -> 0 | J11: =VLOOKUP(A11,'Billing Dimensions'!$A:$N,10,FALSE)-VLOOKUP(A11,'Audit Dimensions'!$A:$N,10,FALSE) -> -2250 | K11: =VLOOKUP(A11,'Billing Dimensions'!$A:$N,11,FALSE)-VLOOKUP(A11,'Audit Dimensions'!$A:$N,11,FALSE) -> 0 | L11: =VLOOKUP(A11,'Billing Dimensions'!$A:$N,12,FALSE)-VLOOKUP(A11,'Audit Dimensions'!$A:$N,12,FALSE) -> 0 | M11: =VLOOKUP(A11,'Billing Dimensions'!$A:$N,13,FALSE)-VLOOKUP(A11,'Audit Dimensions'!$A:$N,13,FALSE) -> 0 | N11: =VLOOKUP(A11,'Billing Dimensions'!$A:$N,14,FALSE)-VLOOKUP(A11,'Audit Dimensions'!$A:$N,14,FALSE) -> 0 | O11: =VLOOKUP(A11,'Billing Dimensions'!A:Q,16,FALSE)-VLOOKUP('Audit VAR'!A11,'Audit Dimensions'!A:P,16,FALSE) -> -3050 | P11: =O11/1000 -> -3.05 | Q11: =(((C11*D11*E11)+(G11*H11*I11)+(K11*L11*M11))/1000000)*35.32 -> 0 | R11: =P11/Q11 -> #DIV/0!
A12: B-RVB-QN | B12: =VLOOKUP(A12,'Billing Dimensions'!A:B,2,FALSE) -> MB | C12: =VLOOKUP(A12,'Billing Dimensions'!$A:$N,3,FALSE)-VLOOKUP(A12,'Audit Dimensions'!$A:$N,3,FALSE) -> -2 | D12: =VLOOKUP(A12,'Billing Dimensions'!$A:$N,4,FALSE)-VLOOKUP(A12,'Audit Dimensions'!$A:$N,4,FALSE) -> -1 | E12: =VLOOKUP(A12,'Billing Dimensions'!$A:$N,5,FALSE)-VLOOKUP(A12,'Audit Dimensions'!$A:$N,5,FALSE) -> 0 | F12: =VLOOKUP(A12,'Billing Dimensions'!$A:$N,6,FALSE)-VLOOKUP(A12,'Audit Dimensions'!$A:$N,6,FALSE) -> -650 | G12: =VLOOKUP(A12,'Billing Dimensions'!$A:$N,7,FALSE)-VLOOKUP(A12,'Audit Dimensions'!$A:$N,7,FALSE) -> -3 | H12: =VLOOKUP(A12,'Billing Dimensions'!$A:$N,8,FALSE)-VLOOKUP(A12,'Audit Dimensions'!$A:$N,8,FALSE) -> 4 | I12: =VLOOKUP(A12,'Billing Dimensions'!$A:$N,9,FALSE)-VLOOKUP(A12,'Audit Dimensions'!$A:$N,9,FALSE) -> 0 | J12: =VLOOKUP(A12,'Billing Dimensions'!$A:$N,10,FALSE)-VLOOKUP(A12,'Audit Dimensions'!$A:$N,10,FALSE) -> -30900 | K12: =VLOOKUP(A12,'Billing Dimensions'!$A:$N,11,FALSE)-VLOOKUP(A12,'Audit Dimensions'!$A:$N,11,FALSE) -> 0 | L12: =VLOOKUP(A12,'Billing Dimensions'!$A:$N,12,FALSE)-VLOOKUP(A12,'Audit Dimensions'!$A:$N,12,FALSE) -> 0 | M12: =VLOOKUP(A12,'Billing Dimensions'!$A:$N,13,FALSE)-VLOOKUP(A12,'Audit Dimensions'!$A:$N,13,FALSE) -> 0 | N12: =VLOOKUP(A12,'Billing Dimensions'!$A:$N,14,FALSE)-VLOOKUP(A12,'Audit Dimensions'!$A:$N,14,FALSE) -> 0 | O12: =VLOOKUP(A12,'Billing Dimensions'!A:Q,16,FALSE)-VLOOKUP('Audit VAR'!A12,'Audit Dimensions'!A:P,16,FALSE) -> -31550 | P12: =O12/1000 -> -31.55 | Q12: =(((C12*D12*E12)+(G12*H12*I12)+(K12*L12*M12))/1000000)*35.32 -> 0 | R12: =P12/Q12 -> #DIV/0!
A13: B-RVB-SN | B13: =VLOOKUP(A13,'Billing Dimensions'!A:B,2,FALSE) -> MB | C13: =VLOOKUP(A13,'Billing Dimensions'!$A:$N,3,FALSE)-VLOOKUP(A13,'Audit Dimensions'!$A:$N,3,FALSE) -> 79 | D13: =VLOOKUP(A13,'Billing Dimensions'!$A:$N,4,FALSE)-VLOOKUP(A13,'Audit Dimensions'!$A:$N,4,FALSE) -> -1 | E13: =VLOOKUP(A13,'Billing Dimensions'!$A:$N,5,FALSE)-VLOOKUP(A13,'Audit Dimensions'!$A:$N,5,FALSE) -> 1 | F13: =VLOOKUP(A13,'Billing Dimensions'!$A:$N,6,FALSE)-VLOOKUP(A13,'Audit Dimensions'!$A:$N,6,FALSE) -> -2540 | G13: =VLOOKUP(A13,'Billing Dimensions'!$A:$N,7,FALSE)-VLOOKUP(A13,'Audit Dimensions'!$A:$N,7,FALSE) -> 2 | H13: =VLOOKUP(A13,'Billing Dimensions'!$A:$N,8,FALSE)-VLOOKUP(A13,'Audit Dimensions'!$A:$N,8,FALSE) -> -2 | I13: =VLOOKUP(A13,'Billing Dimensions'!$A:$N,9,FALSE)-VLOOKUP(A13,'Audit Dimensions'!$A:$N,9,FALSE) -> 0 | J13: =VLOOKUP(A13,'Billing Dimensions'!$A:$N,10,FALSE)-VLOOKUP(A13,'Audit Dimensions'!$A:$N,10,FALSE) -> 1100 | K13: =VLOOKUP(A13,'Billing Dimensions'!$A:$N,11,FALSE)-VLOOKUP(A13,'Audit Dimensions'!$A:$N,11,FALSE) -> 0 | L13: =VLOOKUP(A13,'Billing Dimensions'!$A:$N,12,FALSE)-VLOOKUP(A13,'Audit Dimensions'!$A:$N,12,FALSE) -> 0 | M13: =VLOOKUP(A13,'Billing Dimensions'!$A:$N,13,FALSE)-VLOOKUP(A13,'Audit Dimensions'!$A:$N,13,FALSE) -> 0 | N13: =VLOOKUP(A13,'Billing Dimensions'!$A:$N,14,FALSE)-VLOOKUP(A13,'Audit Dimensions'!$A:$N,14,FALSE) -> 0 | O13: =VLOOKUP(A13,'Billing Dimensions'!A:Q,16,FALSE)-VLOOKUP('Audit VAR'!A13,'Audit Dimensions'!A:P,16,FALSE) -> -1440 | P13: =O13/1000 -> -1.44 | Q13: =(((C13*D13*E13)+(G13*H13*I13)+(K13*L13*M13))/1000000)*35.32 -> -0.00279028 | R13: =P13/Q13 -> 516.07724
A14: B-RVB-D36N | B14: =VLOOKUP(A14,'Billing Dimensions'!A:B,2,FALSE) -> SB | C14: =VLOOKUP(A14,'Billing Dimensions'!$A:$N,3,FALSE)-VLOOKUP(A14,'Audit Dimensions'!$A:$N,3,FALSE) -> 0 | D14: =VLOOKUP(A14,'Billing Dimensions'!$A:$N,4,FALSE)-VLOOKUP(A14,'Audit Dimensions'!$A:$N,4,FALSE) -> 0 | E14: =VLOOKUP(A14,'Billing Dimensions'!$A:$N,5,FALSE)-VLOOKUP(A14,'Audit Dimensions'!$A:$N,5,FALSE) -> 0 | F14: =VLOOKUP(A14,'Billing Dimensions'!$A:$N,6,FALSE)-VLOOKUP(A14,'Audit Dimensions'!$A:$N,6,FALSE) -> -4030 | G14: =VLOOKUP(A14,'Billing Dimensions'!$A:$N,7,FALSE)-VLOOKUP(A14,'Audit Dimensions'!$A:$N,7,FALSE) -> 0 | H14: =VLOOKUP(A14,'Billing Dimensions'!$A:$N,8,FALSE)-VLOOKUP(A14,'Audit Dimensions'!$A:$N,8,FALSE) -> 0 | I14: =VLOOKUP(A14,'Billing Dimensions'!$A:$N,9,FALSE)-VLOOKUP(A14,'Audit Dimensions'!$A:$N,9,FALSE) -> 0 | J14: =VLOOKUP(A14,'Billing Dimensions'!$A:$N,10,FALSE)-VLOOKUP(A14,'Audit Dimensions'!$A:$N,10,FALSE) -> 0 | K14: =VLOOKUP(A14,'Billing Dimensions'!$A:$N,11,FALSE)-VLOOKUP(A14,'Audit Dimensions'!$A:$N,11,FALSE) -> 0 | L14: =VLOOKUP(A14,'Billing Dimensions'!$A:$N,12,FALSE)-VLOOKUP(A14,'Audit Dimensions'!$A:$N,12,FALSE) -> 0 | M14: =VLOOKUP(A14,'Billing Dimensions'!$A:$N,13,FALSE)-VLOOKUP(A14,'Audit Dimensions'!$A:$N,13,FALSE) -> 0 | N14: =VLOOKUP(A14,'Billing Dimensions'!$A:$N,14,FALSE)-VLOOKUP(A14,'Audit Dimensions'!$A:$N,14,FALSE) -> 0 | O14: =VLOOKUP(A14,'Billing Dimensions'!A:Q,16,FALSE)-VLOOKUP('Audit VAR'!A14,'Audit Dimensions'!A:P,16,FALSE) -> -4030 | P14: =O14/1000 -> -4.03 | Q14: =(((C14*D14*E14)+(G14*H14*I14)+(K14*L14*M14))/1000000)*35.32 -> 0 | R14: =P14/Q14 -> #DIV/0!
A15: BT-CO | B15: =VLOOKUP(A15,'Billing Dimensions'!A:B,2,FALSE) -> SB | C15: =VLOOKUP(A15,'Billing Dimensions'!$A:$N,3,FALSE)-VLOOKUP(A15,'Audit Dimensions'!$A:$N,3,FALSE) -> -2 | D15: =VLOOKUP(A15,'Billing Dimensions'!$A:$N,4,FALSE)-VLOOKUP(A15,'Audit Dimensions'!$A:$N,4,FALSE) -> -1 | E15: =VLOOKUP(A15,'Billing Dimensions'!$A:$N,5,FALSE)-VLOOKUP(A15,'Audit Dimensions'!$A:$N,5,FALSE) -> -1 | F15: =VLOOKUP(A15,'Billing Dimensions'!$A:$N,6,FALSE)-VLOOKUP(A15,'Audit Dimensions'!$A:$N,6,FALSE) -> -130 | G15: =VLOOKUP(A15,'Billing Dimensions'!$A:$N,7,FALSE)-VLOOKUP(A15,'Audit Dimensions'!$A:$N,7,FALSE) -> 0 | H15: =VLOOKUP(A15,'Billing Dimensions'!$A:$N,8,FALSE)-VLOOKUP(A15,'Audit Dimensions'!$A:$N,8,FALSE) -> 0 | I15: =VLOOKUP(A15,'Billing Dimensions'!$A:$N,9,FALSE)-VLOOKUP(A15,'Audit Dimensions'!$A:$N,9,FALSE) -> 0 | J15: =VLOOKUP(A15,'Billing Dimensions'!$A:$N,10,FALSE)-VLOOKUP(A15,'Audit Dimensions'!$A:$N,10,FALSE) -> 0 | K15: =VLOOKUP(A15,'Billing Dimensions'!$A:$N,11,FALSE)-VLOOKUP(A15,'Audit Dimensions'!$A:$N,11,FALSE) -> 0 | L15: =VLOOKUP(A15,'Billing Dimensions'!$A:$N,12,FALSE)-VLOOKUP(A15,'Audit Dimensions'!$A:$N,12,FALSE) -> 0 | M15: =VLOOKUP(A15,'Billing Dimensions'!$A:$N,13,FALSE)-VLOOKUP(A15,'Audit Dimensions'!$A:$N,13,FALSE) -> 0 | N15: =VLOOKUP(A15,'Billing Dimensions'!$A:$N,14,FALSE)-VLOOKUP(A15,'Audit Dimensions'!$A:$N,14,FALSE) -> 0 | O15: =VLOOKUP(A15,'Billing Dimensions'!A:Q,16,FALSE)-VLOOKUP('Audit VAR'!A15,'Audit Dimensions'!A:P,16,FALSE) -> -130 | P15: =O15/1000 -> -0.13 | Q15: =(((C15*D15*E15)+(G15*H15*I15)+(K15*L15*M15))/1000000)*35.32 -> -7.064e-05 | R15: =P15/Q15 -> 1840.3171
... A270: TU-BKMT | B270: =VLOOKUP(A270,'Billing Dimensions'!A:B,2,FALSE) -> SB | C270: =VLOOKUP(A270,'Billing Dimensions'!$A:$N,3,FALSE)-VLOOKUP(A270,'Audit Dimensions'!$A:$N,3,FALSE) -> #N/A | D270: =VLOOKUP(A270,'Billing Dimensions'!$A:$N,4,FALSE)-VLOOKUP(A270,'Audit Dimensions'!$A:$N,4,FALSE) -> #N/A | E270: =VLOOKUP(A270,'Billing Dimensions'!$A:$N,5,FALSE)-VLOOKUP(A270,'Audit Dimensions'!$A:$N,5,FALSE) -> #N/A | F270: =VLOOKUP(A270,'Billing Dimensions'!$A:$N,6,FALSE)-VLOOKUP(A270,'Audit Dimensions'!$A:$N,6,FALSE) -> #N/A | G270: =VLOOKUP(A270,'Billing Dimensions'!$A:$N,7,FALSE)-VLOOKUP(A270,'Audit Dimensions'!$A:$N,7,FALSE) -> #N/A | H270: =VLOOKUP(A270,'Billing Dimensions'!$A:$N,8,FALSE)-VLOOKUP(A270,'Audit Dimensions'!$A:$N,8,FALSE) -> #N/A | I270: =VLOOKUP(A270,'Billing Dimensions'!$A:$N,9,FALSE)-VLOOKUP(A270,'Audit Dimensions'!$A:$N,9,FALSE) -> #N/A | J270: =VLOOKUP(A270,'Billing Dimensions'!$A:$N,10,FALSE)-VLOOKUP(A270,'Audit Dimensions'!$A:$N,10,FALSE) -> #N/A | K270: =VLOOKUP(A270,'Billing Dimensions'!$A:$N,11,FALSE)-VLOOKUP(A270,'Audit Dimensions'!$A:$N,11,FALSE) -> #N/A | L270: =VLOOKUP(A270,'Billing Dimensions'!$A:$N,12,FALSE)-VLOOKUP(A270,'Audit Dimensions'!$A:$N,12,FALSE) -> #N/A | M270: =VLOOKUP(A270,'Billing Dimensions'!$A:$N,13,FALSE)-VLOOKUP(A270,'Audit Dimensions'!$A:$N,13,FALSE) -> #N/A | N270: =VLOOKUP(A270,'Billing Dimensions'!$A:$N,14,FALSE)-VLOOKUP(A270,'Audit Dimensions'!$A:$N,14,FALSE) -> #N/A | O270: =VLOOKUP(A270,'Billing Dimensions'!A:Q,16,FALSE)-VLOOKUP('Audit VAR'!A270,'Audit Dimensions'!A:P,16,FALSE) -> #N/A | P270: =O270/1000 -> #N/A | Q270: =(((C270*D270*E270)+(G270*H270*I270)+(K270*L270*M270))/1000000)*35.32 -> #N/A | R270: =P270/Q270 -> #N/A
A271: KH-TOC-18 | B271: SB | C271: 39 | D271: 30 | E271: 8 | F271: 3000 | G271: =VLOOKUP(A271,'Billing Dimensions'!$A:$N,7,FALSE)-VLOOKUP(A271,'Audit Dimensions'!$A:$N,7,FALSE) -> 0 | H271: =VLOOKUP(A271,'Billing Dimensions'!$A:$N,8,FALSE)-VLOOKUP(A271,'Audit Dimensions'!$A:$N,8,FALSE) -> 0 | I271: =VLOOKUP(A271,'Billing Dimensions'!$A:$N,9,FALSE)-VLOOKUP(A271,'Audit Dimensions'!$A:$N,9,FALSE) -> 0 | J271: =VLOOKUP(A271,'Billing Dimensions'!$A:$N,10,FALSE)-VLOOKUP(A271,'Audit Dimensions'!$A:$N,10,FALSE) -> 0 | K271: =VLOOKUP(A271,'Billing Dimensions'!$A:$N,11,FALSE)-VLOOKUP(A271,'Audit Dimensions'!$A:$N,11,FALSE) -> 0 | L271: =VLOOKUP(A271,'Billing Dimensions'!$A:$N,12,FALSE)-VLOOKUP(A271,'Audit Dimensions'!$A:$N,12,FALSE) -> 0 | M271: =VLOOKUP(A271,'Billing Dimensions'!$A:$N,13,FALSE)-VLOOKUP(A271,'Audit Dimensions'!$A:$N,13,FALSE) -> 0 | N271: =VLOOKUP(A271,'Billing Dimensions'!$A:$N,14,FALSE)-VLOOKUP(A271,'Audit Dimensions'!$A:$N,14,FALSE) -> 0 | O271: =VLOOKUP(A271,'Billing Dimensions'!A:Q,16,FALSE)-VLOOKUP('Audit VAR'!A271,'Audit Dimensions'!A:P,16,FALSE) -> -600 | P271: =O271/1000 -> -0.6 | Q271: =(((C271*D271*E271)+(G271*H271*I271)+(K271*L271*M271))/1000000)*35.32 -> 0.3305952 | R271: =P271/Q271 -> -1.8149084
A272: KH-TOC-40 | B272: SB | C272: 65 | D272: 35 | E272: 8 | F272: 5000 | G272: =VLOOKUP(A272,'Billing Dimensions'!$A:$N,7,FALSE)-VLOOKUP(A272,'Audit Dimensions'!$A:$N,7,FALSE) -> 0 | H272: =VLOOKUP(A272,'Billing Dimensions'!$A:$N,8,FALSE)-VLOOKUP(A272,'Audit Dimensions'!$A:$N,8,FALSE) -> 0 | I272: =VLOOKUP(A272,'Billing Dimensions'!$A:$N,9,FALSE)-VLOOKUP(A272,'Audit Dimensions'!$A:$N,9,FALSE) -> 0 | J272: =VLOOKUP(A272,'Billing Dimensions'!$A:$N,10,FALSE)-VLOOKUP(A272,'Audit Dimensions'!$A:$N,10,FALSE) -> 0 | K272: =VLOOKUP(A272,'Billing Dimensions'!$A:$N,11,FALSE)-VLOOKUP(A272,'Audit Dimensions'!$A:$N,11,FALSE) -> 0 | L272: =VLOOKUP(A272,'Billing Dimensions'!$A:$N,12,FALSE)-VLOOKUP(A272,'Audit Dimensions'!$A:$N,12,FALSE) -> 0 | M272: =VLOOKUP(A272,'Billing Dimensions'!$A:$N,13,FALSE)-VLOOKUP(A272,'Audit Dimensions'!$A:$N,13,FALSE) -> 0 | N272: =VLOOKUP(A272,'Billing Dimensions'!$A:$N,14,FALSE)-VLOOKUP(A272,'Audit Dimensions'!$A:$N,14,FALSE) -> 0 | O272: =VLOOKUP(A272,'Billing Dimensions'!A:Q,16,FALSE)-VLOOKUP('Audit VAR'!A272,'Audit Dimensions'!A:P,16,FALSE) -> 0 | P272: =O272/1000 -> 0 | Q272: =(((C272*D272*E272)+(G272*H272*I272)+(K272*L272*M272))/1000000)*35.32 -> 0.642824 | R272: =P272/Q272 -> 0
A273: SR-BKN-T | B273: SB | C273: 1 | D273: 1 | E273: 1 | F273: 37000 | G273: =VLOOKUP(A273,'Billing Dimensions'!$A:$N,7,FALSE)-VLOOKUP(A273,'Audit Dimensions'!$A:$N,7,FALSE) -> 0 | H273: =VLOOKUP(A273,'Billing Dimensions'!$A:$N,8,FALSE)-VLOOKUP(A273,'Audit Dimensions'!$A:$N,8,FALSE) -> 0 | I273: =VLOOKUP(A273,'Billing Dimensions'!$A:$N,9,FALSE)-VLOOKUP(A273,'Audit Dimensions'!$A:$N,9,FALSE) -> 0 | J273: =VLOOKUP(A273,'Billing Dimensions'!$A:$N,10,FALSE)-VLOOKUP(A273,'Audit Dimensions'!$A:$N,10,FALSE) -> 0 | K273: =VLOOKUP(A273,'Billing Dimensions'!$A:$N,11,FALSE)-VLOOKUP(A273,'Audit Dimensions'!$A:$N,11,FALSE) -> 0 | L273: =VLOOKUP(A273,'Billing Dimensions'!$A:$N,12,FALSE)-VLOOKUP(A273,'Audit Dimensions'!$A:$N,12,FALSE) -> 0 | M273: =VLOOKUP(A273,'Billing Dimensions'!$A:$N,13,FALSE)-VLOOKUP(A273,'Audit Dimensions'!$A:$N,13,FALSE) -> 0 | N273: =VLOOKUP(A273,'Billing Dimensions'!$A:$N,14,FALSE)-VLOOKUP(A273,'Audit Dimensions'!$A:$N,14,FALSE) -> 0 | O273: =VLOOKUP(A273,'Billing Dimensions'!A:Q,16,FALSE)-VLOOKUP('Audit VAR'!A273,'Audit Dimensions'!A:P,16,FALSE) -> 0 | P273: =O273/1000 -> 0 | Q273: =(((C273*D273*E273)+(G273*H273*I273)+(K273*L273*M273))/1000000)*35.32 -> 3.532e-05 | R273: =P273/Q273 -> 0
A274: TS-NL-ST | B274: SB | C274: 1 | D274: 1 | E274: 1 | F274: 1792 | G274: =VLOOKUP(A274,'Billing Dimensions'!$A:$N,7,FALSE)-VLOOKUP(A274,'Audit Dimensions'!$A:$N,7,FALSE) -> 0 | H274: =VLOOKUP(A274,'Billing Dimensions'!$A:$N,8,FALSE)-VLOOKUP(A274,'Audit Dimensions'!$A:$N,8,FALSE) -> 0 | I274: =VLOOKUP(A274,'Billing Dimensions'!$A:$N,9,FALSE)-VLOOKUP(A274,'Audit Dimensions'!$A:$N,9,FALSE) -> 0 | J274: =VLOOKUP(A274,'Billing Dimensions'!$A:$N,10,FALSE)-VLOOKUP(A274,'Audit Dimensions'!$A:$N,10,FALSE) -> 0 | K274: =VLOOKUP(A274,'Billing Dimensions'!$A:$N,11,FALSE)-VLOOKUP(A274,'Audit Dimensions'!$A:$N,11,FALSE) -> 0 | L274: =VLOOKUP(A274,'Billing Dimensions'!$A:$N,12,FALSE)-VLOOKUP(A274,'Audit Dimensions'!$A:$N,12,FALSE) -> 0 | M274: =VLOOKUP(A274,'Billing Dimensions'!$A:$N,13,FALSE)-VLOOKUP(A274,'Audit Dimensions'!$A:$N,13,FALSE) -> 0 | N274: =VLOOKUP(A274,'Billing Dimensions'!$A:$N,14,FALSE)-VLOOKUP(A274,'Audit Dimensions'!$A:$N,14,FALSE) -> 0 | O274: =VLOOKUP(A274,'Billing Dimensions'!A:Q,16,FALSE)-VLOOKUP('Audit VAR'!A274,'Audit Dimensions'!A:P,16,FALSE) -> 1550 | P274: =O274/1000 -> 1.55 | Q274: =(((C274*D274*E274)+(G274*H274*I274)+(K274*L274*M274))/1000000)*35.32 -> 3.532e-05 | R274: =P274/Q274 -> 43884.485
